Workbook
Name 部門: #REF!
Name 單位: #REF!
Name 供應商: #REF!
Name 類別: #REF!
Name 料號: 物料本月库存明細!$C:$C
Name 稅別: #REF!

Sheet ROJWYMJ

Sheet 物料月初库存
D1: 7.6盘点半成品
A2: 序号 | B2: 盘点日期 | C2: 料号 | D2: 机种名称 | E2: 单位 | F2: 数量 | G2: 备注工艺 | I2: 本月库存 | J2: 备注
B3: 2026.7.6盘点 | D3: =VLOOKUP($C3,物料本月库存明細!$B:$J,2,0) -> #N/A | E3: =VLOOKUP($C3,物料本月库存明細!$B:$J,5,0) -> #N/A | I3: =VLOOKUP($C3,物料本月库存明細!$B:$J,9,0) -> #N/A
D4: =VLOOKUP($C4,物料本月库存明細!$B:$J,2,0) -> #N/A | E4: =VLOOKUP($C4,物料本月库存明細!$B:$J,5,0) -> #N/A | I4: =VLOOKUP($C4,物料本月库存明細!$B:$J,9,0) -> #N/A
C5: XFT035-ZG | D5: =VLOOKUP($C5,物料本月库存明細!$B:$J,2,0) -> （001）Kreka Harrier Heatsink Tool/PHSP | E5: =VLOOKUP($C5,物料本月库存明細!$B:$J,5,0) -> PCS | F5: 1380 | I5: =VLOOKUP($C5,物料本月库存明細!$B:$J,9,0) -> 1380
C6: XFT035-ZYM | D6: =VLOOKUP($C6,物料本月库存明細!$B:$J,2,0) -> （001）Kreka Harrier Heatsink Tool/PHSP | E6: =VLOOKUP($C6,物料本月库存明細!$B:$J,5,0) -> PCS | F6: 799 | I6: =VLOOKUP($C6,物料本月库存明細!$B:$J,9,0) -> 799
C7: XFT050-Y | D7: =VLOOKUP($C7,物料本月库存明細!$B:$J,2,0) -> CG-00077 | E7: =VLOOKUP($C7,物料本月库存明細!$B:$J,5,0) -> PCS | F7: 200 | I7: =VLOOKUP($C7,物料本月库存明細!$B:$J,9,0) -> 200
C8: LX0003-P | D8: =VLOOKUP($C8,物料本月库存明細!$B:$J,2,0) -> T93-13 | E8: =VLOOKUP($C8,物料本月库存明細!$B:$J,5,0) -> PCS | F8: 2487 | I8: =VLOOKUP($C8,物料本月库存明細!$B:$J,9,0) -> 2487
C9: SRY002-Y | D9: =VLOOKUP($C9,物料本月库存明細!$B:$J,2,0) -> 托架 | E9: =VLOOKUP($C9,物料本月库存明細!$B:$J,5,0) -> PCS | F9: 278 | I9: =VLOOKUP($C9,物料本月库存明細!$B:$J,9,0) -> 278
C10: HH0004-Y | D10: =VLOOKUP($C10,物料本月库存明細!$B:$J,2,0) -> 小金童铝连杆 | E10: =VLOOKUP($C10,物料本月库存明細!$B:$J,5,0) -> PCS | F10: 13300 | I10: =VLOOKUP($C10,物料本月库存明細!$B:$J,9,0) -> 0
C11: HH0026-Y | D11: =VLOOKUP($C11,物料本月库存明細!$B:$J,2,0) -> 铝底座/8526 | E11: =VLOOKUP($C11,物料本月库存明細!$B:$J,5,0) -> PCS | F11: 8110 | I11: =VLOOKUP($C11,物料本月库存明細!$B:$J,9,0) -> 0
C12: HH0031-Z/G | D12: =VLOOKUP($C12,物料本月库存明細!$B:$J,2,0) -> HH8525/8513滑杆（同8527滑杆） | E12: =VLOOKUP($C12,物料本月库存明細!$B:$J,5,0) -> PCS | F12: 189 | I12: =VLOOKUP($C12,物料本月库存明細!$B:$J,9,0) -> 189
C13: HH0036-CNC | D13: =VLOOKUP($C13,物料本月库存明細!$B:$J,2,0) -> 8592连杆 | E13: =VLOOKUP($C13,物料本月库存明細!$B:$J,5,0) -> PCS | F13: 3996 | I13: =VLOOKUP($C13,物料本月库存明細!$B:$J,9,0) -> 3996
C14: OFG004-ZY | D14: =VLOOKUP($C14,物料本月库存明細!$B:$J,2,0) -> (YC013600237900)设变后(YC013600237901) | E14: =VLOOKUP($C14,物料本月库存明細!$B:$J,5,0) -> PCS | F14: 3580 | I14: =VLOOKUP($C14,物料本月库存明細!$B:$J,9,0) -> 3580
C15: OFG007-ZY | D15: =VLOOKUP($C15,物料本月库存明細!$B:$J,2,0) -> （YC013600304000）MS11后壳 | E15: =VLOOKUP($C15,物料本月库存明細!$B:$J,5,0) -> PCS | F15: 18195 | I15: =VLOOKUP($C15,物料本月库存明細!$B:$J,9,0) -> 18195
C16: OFG014-DY | D16: =VLOOKUP($C16,物料本月库存明細!$B:$J,2,0) -> YC013600155200(CAM后壳） | E16: =VLOOKUP($C16,物料本月库存明細!$B:$J,5,0) -> PCS | F16: 469 | I16: =VLOOKUP($C16,物料本月库存明細!$B:$J,9,0) -> 469
... C26: RB014 | D26: =VLOOKUP($C26,物料本月库存明細!$B:$J,2,0) -> 819/826轴套 | E26: =VLOOKUP($C26,物料本月库存明細!$B:$J,5,0) -> PCS | F26: 3780 | I26: =VLOOKUP($C26,物料本月库存明細!$B:$J,9,0) -> 0
C27: RB015-KQ | D27: =VLOOKUP($C27,物料本月库存明細!$B:$J,2,0) -> 819头壳（含轴套） | E27: =VLOOKUP($C27,物料本月库存明細!$B:$J,5,0) -> PCS | F27: =2877 -> 2877 | I27: =VLOOKUP($C27,物料本月库存明細!$B:$J,9,0) -> 2877
C28: RB016-Y | D28: =VLOOKUP($C28,物料本月库存明細!$B:$J,2,0) -> 826头壳（含轴套） | E28: =VLOOKUP($C28,物料本月库存明細!$B:$J,5,0) -> PCS | F28: 1800 | I28: =VLOOKUP($C28,物料本月库存明細!$B:$J,9,0) -> 0
C29: RB023-Y | D29: =VLOOKUP($C29,物料本月库存明細!$B:$J,2,0) -> 扳手828头壳 | E29: =VLOOKUP($C29,物料本月库存明細!$B:$J,5,0) -> PCS | F29: =210 -> 210 | I29: =VLOOKUP($C29,物料本月库存明細!$B:$J,9,0) -> 0
C30: RB029-M | D30: =VLOOKUP($C30,物料本月库存明細!$B:$J,2,0) -> 扳手809S SATA头壳（世达） | E30: =VLOOKUP($C30,物料本月库存明細!$B:$J,5,0) -> PCS | F30: 2000 | I30: =VLOOKUP($C30,物料本月库存明細!$B:$J,9,0) -> 2038
C31: RB029-M | D31: 扳手809S SATA头壳（世达） | E31: =VLOOKUP($C31,[1]成品本月库存!$B:$J,5,0) -> #N/A | F31: 38 | G31: 烤漆不良
C32: RB031-P | D32: =VLOOKUP($C32,物料本月库存明細!$B:$J,2,0) -> 扳手818S SATA端盖（世达） | E32: =VLOOKUP($C32,物料本月库存明細!$B:$J,5,0) -> PCS | F32: 1028 | I32: =VLOOKUP($C32,物料本月库存明細!$B:$J,9,0) -> 1028
C33: RB034-PW | D33: =VLOOKUP($C33,物料本月库存明細!$B:$J,2,0) -> 黄油枪HY01A齿轮箱 | E33: =VLOOKUP($C33,物料本月库存明細!$B:$J,5,0) -> PCS | F33: =5+142+37 -> 184 | I33: =VLOOKUP($C33,物料本月库存明細!$B:$J,9,0) -> 37
C34: RB034-CNC | D34: =VLOOKUP($C34,物料本月库存明細!$B:$J,2,0) -> 黄油枪HY01A齿轮箱 | E34: =VLOOKUP($C34,物料本月库存明細!$B:$J,5,0) -> PCS | F34: 185 | I34: =VLOOKUP($C34,物料本月库存明細!$B:$J,9,0) -> 185
C35: YL001-Y | D35: =VLOOKUP($C35,物料本月库存明細!$B:$J,2,0) -> 1A321W1M001-0A(EL-321W-GL04 铝壳） | E35: =VLOOKUP($C35,物料本月库存明細!$B:$J,5,0) -> PCS | F35: 2400 | I35: =VLOOKUP($C35,物料本月库存明細!$B:$J,9,0) -> 0
C36: YL001-DM | D36: =VLOOKUP($C36,物料本月库存明細!$B:$J,2,0) -> 1A321W1M001-0A(EL-321W-GL04 铝壳） | E36: =VLOOKUP($C36,物料本月库存明細!$B:$J,5,0) -> PCS | F36: 800 | I36: =VLOOKUP($C36,物料本月库存明細!$B:$J,9,0) -> 2400
C37: KT008-Y | D37: =VLOOKUP($C37,物料本月库存明細!$B:$J,2,0) -> M82双目支架 | E37: =VLOOKUP($C37,物料本月库存明細!$B:$J,5,0) -> PCS | F37: 86 | I37: =VLOOKUP($C37,物料本月库存明細!$B:$J,9,0) -> 86
C38: HAPX005-Y | D38: =VLOOKUP($C38,物料本月库存明細!$B:$J,2,0) -> 电子锁铝外壳下壳 | E38: =VLOOKUP($C38,物料本月库存明細!$B:$J,5,0) -> PCS | F38: 0 | I38: =VLOOKUP($C38,物料本月库存明細!$B:$J,9,0) -> 0
C39: HAPX005-YM | D39: =VLOOKUP($C39,物料本月库存明細!$B:$J,2,0) -> 电子锁铝外壳下壳 | E39: =VLOOKUP($C39,物料本月库存明細!$B:$J,5,0) -> PCS | F39: 469 | I39: =VLOOKUP($C39,物料本月库存明細!$B:$J,9,0) -> 469
C40: TST003-Y | D40: =VLOOKUP($C40,物料本月库存明細!$B:$J,2,0) -> E1S-02-B2 | E40: =VLOOKUP($C40,物料本月库存明細!$B:$J,5,0) -> PCS | F40: 0 | I40: =VLOOKUP($C40,物料本月库存明細!$B:$J,9,0) -> 0
C41: TST003-DM | D41: =VLOOKUP($C41,物料本月库存明細!$B:$J,2,0) -> E1S-02-B2 | E41: =VLOOKUP($C41,物料本月库存明細!$B:$J,5,0) -> PCS | F41: 0 | I41: =VLOOKUP($C41,物料本月库存明細!$B:$J,9,0) -> 0
C42: TST003-CNC | D42: =VLOOKUP($C42,物料本月库存明細!$B:$J,2,0) -> E1S-02-B2 | E42: =VLOOKUP($C42,物料本月库存明細!$B:$J,5,0) -> PCS | F42: 647 | I42: =VLOOKUP($C42,物料本月库存明細!$B:$J,9,0) -> 647
C43: HX001-Y | D43: =VLOOKUP($C43,物料本月库存明細!$B:$J,2,0) -> 手持屏T3（硅胶按键） | E43: =VLOOKUP($C43,物料本月库存明細!$B:$J,5,0) -> PCS | F43: 0 | I43: =VLOOKUP($C43,物料本月库存明細!$B:$J,9,0) -> 0
C44: WN006--Y | D44: =VLOOKUP($C44,物料本月库存明細!$B:$J,2,0) -> 锁-2 | E44: =VLOOKUP($C44,物料本月库存明細!$B:$J,5,0) -> PCS | F44: 1840 | I44: =VLOOKUP($C44,物料本月库存明細!$B:$J,9,0) -> 1840
C45: SM005-Y | D45: =VLOOKUP($C45,物料本月库存明細!$B:$J,2,0) -> SD04-POE外壳（中框支架） | E45: =VLOOKUP($C45,物料本月库存明細!$B:$J,5,0) -> PCS | F45: 140 | I45: =VLOOKUP($C45,物料本月库存明細!$B:$J,9,0) -> 140
... C65: SRY001-Z/M | D65: =VLOOKUP($C65,物料本月库存明細!$B:$J,2,0) -> WL52-bottom(WL92) | E65: =VLOOKUP($C65,物料本月库存明細!$B:$J,5,0) -> PCS | F65: 9605 | I65: =VLOOKUP($C65,物料本月库存明細!$B:$J,9,0) -> 251
D66: =VLOOKUP($C66,物料本月库存明細!$B:$J,2,0) -> #N/A | E66: =VLOOKUP($C66,物料本月库存明細!$B:$J,5,0) -> #N/A | I66: =VLOOKUP($C66,物料本月库存明細!$B:$J,9,0) -> #N/A

Sheet 半成品入库明细
A1: 厂商 | B1: 日 期 | C1: 单据编号 | D1: 料号 | E1: 机种名称 | F1: 单位 | G1: 数量 | H1: 备注 | J1: 本月库存
A2: 压铸 | B2: 46209 | C2: 0001251 | D2: RB024-Y | E2: =VLOOKUP($D2,物料本月库存明細!$B:$J,2,0) -> 扳手828端盖 | F2: =VLOOKUP($D2,物料本月库存明細!$B:$J,5,0) -> PCS | G2: 720 | J2: =VLOOKUP($D2,物料本月库存明細!$B:$J,9,0) -> 0
A3: 压铸 | B3: 46209 | C3: 0001251 | D3: RYZM001-Y | E3: =VLOOKUP($D3,物料本月库存明細!$B:$J,2,0) -> 轴承主体支架 | F3: =VLOOKUP($D3,物料本月库存明細!$B:$J,5,0) -> PCS | G3: 1239 | J3: =VLOOKUP($D3,物料本月库存明細!$B:$J,9,0) -> 1239
A4: 压铸 | B4: 46209 | C4: 0001251 | D4: RYZM002-Y | E4: =VLOOKUP($D4,物料本月库存明細!$B:$J,2,0) -> 相机卡扣 | F4: =VLOOKUP($D4,物料本月库存明細!$B:$J,5,0) -> PCS | G4: 4350 | J4: =VLOOKUP($D4,物料本月库存明細!$B:$J,9,0) -> 4350
A5: 压铸 | B5: 46209 | C5: 0001251 | D5: RB023-Y | E5: =VLOOKUP($D5,物料本月库存明細!$B:$J,2,0) -> 扳手828头壳 | F5: =VLOOKUP($D5,物料本月库存明細!$B:$J,5,0) -> PCS | G5: 526 | J5: =VLOOKUP($D5,物料本月库存明細!$B:$J,9,0) -> 0
A6: 压铸 | B6: 46209 | C6: 0001251 | D6: LX0010-Y | E6: =VLOOKUP($D6,物料本月库存明細!$B:$J,2,0) -> T93-20 | F6: =VLOOKUP($D6,物料本月库存明細!$B:$J,5,0) -> PCS | G6: 12480 | J6: =VLOOKUP($D6,物料本月库存明細!$B:$J,9,0) -> 14400
A7: 压铸 | B7: 46209 | C7: 0001251 | D7: RB004-Y | E7: =VLOOKUP($D7,物料本月库存明細!$B:$J,2,0) -> 起子机2108-W头壳（230N头壳无轴套） | F7: =VLOOKUP($D7,物料本月库存明細!$B:$J,5,0) -> PCS | G7: 3200 | J7: =VLOOKUP($D7,物料本月库存明細!$B:$J,9,0) -> 0
A8: 压铸 | B8: 46209 | C8: 0001251 | D8: KT006-Y | E8: =VLOOKUP($D8,物料本月库存明細!$B:$J,2,0) -> 超频主机上1个单芯盖（PL9-01100-00-0A) | F8: =VLOOKUP($D8,物料本月库存明細!$B:$J,5,0) -> PCS | G8: 1014 | J8: =VLOOKUP($D8,物料本月库存明細!$B:$J,9,0) -> 1014
A9: 锦宇树 | B9: 46209 | C9: 0006302 | D9: HH0028-C | E9: =VLOOKUP($D9,物料本月库存明細!$B:$J,2,0) -> 8527旋钮 | F9: =VLOOKUP($D9,物料本月库存明細!$B:$J,5,0) -> PCS | G9: 1064 | J9: =VLOOKUP($D9,物料本月库存明細!$B:$J,9,0) -> 0
A10: 锦宇树 | B10: 46209 | C10: 0006302 | D10: HH0023-C | E10: =VLOOKUP($D10,物料本月库存明細!$B:$J,2,0) -> HH8513传导片 | F10: =VLOOKUP($D10,物料本月库存明細!$B:$J,5,0) -> PCS | G10: 6160 | J10: =VLOOKUP($D10,物料本月库存明細!$B:$J,9,0) -> 0
A11: 锦宇树 | B11: 46209 | C11: 0006302 | D11: RB027-KQ | E11: =VLOOKUP($D11,物料本月库存明細!$B:$J,2,0) -> 扳手810STK2头壳 | F11: =VLOOKUP($D11,物料本月库存明細!$B:$J,5,0) -> PCS | G11: 30 | H11: 素材不良退回30个 | J11: =VLOOKUP($D11,物料本月库存明細!$B:$J,9,0) -> 2215
A12: 锦宇树 | B12: 46209 | C12: 0006302 | D12: RB026-KQ | E12: =VLOOKUP($D12,物料本月库存明細!$B:$J,2,0) -> 扳手806S头壳 SD | F12: =VLOOKUP($D12,物料本月库存明細!$B:$J,5,0) -> PCS | G12: 24 | H12: 素材不良退回24个 | J12: =VLOOKUP($D12,物料本月库存明細!$B:$J,9,0) -> 24
A13: 锦拓 | B13: 46209 | C13: 0005834 | D13: LX0010-P | E13: =VLOOKUP($D13,物料本月库存明細!$B:$J,2,0) -> T93-20 | F13: =VLOOKUP($D13,物料本月库存明細!$B:$J,5,0) -> PCS | G13: 14198 | J13: =VLOOKUP($D13,物料本月库存明細!$B:$J,9,0) -> 12480
A14: 博鑫 | B14: 46206 | C14: 0002193 | D14: RB004 | E14: =VLOOKUP($D14,物料本月库存明細!$B:$J,2,0) -> 2108起子机轴套（230N轴套） | F14: =VLOOKUP($D14,物料本月库存明細!$B:$J,5,0) -> PCS | G14: 5000 | J14: =VLOOKUP($D14,物料本月库存明細!$B:$J,9,0) -> 5000
A15: 压铸 | B15: 46210 | C15: 0001252 | D15: LX0010-Y | E15: =VLOOKUP($D15,物料本月库存明細!$B:$J,2,0) -> T93-20 | F15: =VLOOKUP($D15,物料本月库存明細!$B:$J,5,0) -> PCS | G15: 9600 | J15: =VLOOKUP($D15,物料本月库存明細!$B:$J,9,0) -> 14400
A16: 青元山 | B16: 46209 | C16: 0001178 | D16: DW008-PG | E16: =VLOOKUP($D16,物料本月库存明細!$B:$J,2,0) -> W2808-1850N挂钩 | F16: =VLOOKUP($D16,物料本月库存明細!$B:$J,5,0) -> KG | G16: 2780 | J16: =VLOOKUP($D16,物料本月库存明細!$B:$J,9,0) -> 2780
A17: 青元山 | B17: 46209 | C17: 0001178 | D17: DW003-PG | E17: =VLOOKUP($D17,物料本月库存明細!$B:$J,2,0) -> W2805-850N头壳 | F17: =VLOOKUP($D17,物料本月库存明細!$B:$J,5,0) -> KG | G17: 50 | J17: =VLOOKUP($D17,物料本月库存明細!$B:$J,9,0) -> 0
A18: 青元山 | B18: 46209 | C18: 0001178 | D18: DW004-PG | E18: =VLOOKUP($D18,物料本月库存明細!$B:$J,2,0) -> W2805-850N端盖 | F18: =VLOOKUP($D18,物料本月库存明細!$B:$J,5,0) -> KG | G18: 50 | J18: =VLOOKUP($D18,物料本月库存明細!$B:$J,9,0) -> 0
A19: 锦宇树 | B19: 46210 | C19: 0006303 | D19: RB002-KQ | E19: =VLOOKUP($D19,物料本月库存明細!$B:$J,2,0) -> 扳手809头壳(含轴套) | F19: =VLOOKUP($D19,物料本月库存明細!$B:$J,5,0) -> PCS | G19: 21 | H19: 素材不良退回21个 | J19: =VLOOKUP($D19,物料本月库存明細!$B:$J,9,0) -> 21
A20: 全才 | B20: 46210 | C20: 0005756 | D20: HH0023-PG | E20: =VLOOKUP($D20,物料本月库存明細!$B:$J,2,0) -> HH8513传导片 | F20: =VLOOKUP($D20,物料本月库存明細!$B:$J,5,0) -> PCS | G20: 200 | J20: =VLOOKUP($D20,物料本月库存明細!$B:$J,9,0) -> 200
A21: 锦拓 | B21: 46210 | C21: 0005835 | D21: HH0028-P | E21: =VLOOKUP($D21,物料本月库存明細!$B:$J,2,0) -> 8527旋钮 | F21: =VLOOKUP($D21,物料本月库存明細!$B:$J,5,0) -> PCS | G21: 1064 | J21: =VLOOKUP($D21,物料本月库存明細!$B:$J,9,0) -> 1064
A22: 锦拓 | B22: 46210 | C22: 0005835 | D22: LX0010-P | E22: =VLOOKUP($D22,物料本月库存明細!$B:$J,2,0) -> T93-20 | F22: =VLOOKUP($D22,物料本月库存明細!$B:$J,5,0) -> PCS | G22: 12480 | J22: =VLOOKUP($D22,物料本月库存明細!$B:$J,9,0) -> 12480
A23: 锦拓 | B23: 46210 | C23: 0005835 | D23: RB024-P | E23: =VLOOKUP($D23,物料本月库存明細!$B:$J,2,0) -> 扳手828端盖 | F23: =VLOOKUP($D23,物料本月库存明細!$B:$J,5,0) -> PCS | G23: 720 | J23: =VLOOKUP($D23,物料本月库存明細!$B:$J,9,0) -> 720
A24: 麦凯良 | B24: 46210 | C24: 0006329 | D24: YL001-DM | E24: =VLOOKUP($D24,物料本月库存明細!$B:$J,2,0) -> 1A321W1M001-0A(EL-321W-GL04 铝壳） | F24: =VLOOKUP($D24,物料本月库存明細!$B:$J,5,0) -> PCS | G24: 1600 | J24: =VLOOKUP($D24,物料本月库存明細!$B:$J,9,0) -> 2400
A25: 麦凯良 | B25: 46210 | C25: 0006329 | D25: RB015-DM | E25: =VLOOKUP($D25,物料本月库存明細!$B:$J,2,0) -> 819头壳（含轴套） | F25: =VLOOKUP($D25,物料本月库存明細!$B:$J,5,0) -> PCS | G25: 1960 | J25: =VLOOKUP($D25,物料本月库存明細!$B:$J,9,0) -> 1960
A26: 压铸 | B26: 46211 | C26: 0001254 | D26: LX00016-Y | E26: =VLOOKUP($D26,物料本月库存明細!$B:$J,2,0) -> JK111-03机壳(无牙） | F26: =VLOOKUP($D26,物料本月库存明細!$B:$J,5,0) -> PCS | G26: 1620 | J26: =VLOOKUP($D26,物料本月库存明細!$B:$J,9,0) -> 3240
A27: 压铸 | B27: 46211 | C27: 0001254 | D27: RB004-Y | E27: =VLOOKUP($D27,物料本月库存明細!$B:$J,2,0) -> 起子机2108-W头壳（230N头壳无轴套） | F27: =VLOOKUP($D27,物料本月库存明細!$B:$J,5,0) -> PCS | G27: 2395 | H27: 设变后 | J27: =VLOOKUP($D27,物料本月库存明細!$B:$J,9,0) -> 0
A28: 压铸 | B28: 46211 | C28: 0001254 | D28: LX00016-Y | E28: =VLOOKUP($D28,物料本月库存明細!$B:$J,2,0) -> JK111-03机壳(无牙） | F28: =VLOOKUP($D28,物料本月库存明細!$B:$J,5,0) -> PCS | G28: 1620 | J28: =VLOOKUP($D28,物料本月库存明細!$B:$J,9,0) -> 3240
A29: 压铸 | B29: 46211 | C29: 0001254 | D29: KBL002-Y | E29: =VLOOKUP($D29,物料本月库存明細!$B:$J,2,0) -> 压盖 | F29: =VLOOKUP($D29,物料本月库存明細!$B:$J,5,0) -> PCS | G29: 12500 | J29: =VLOOKUP($D29,物料本月库存明細!$B:$J,9,0) -> 12500
A30: 压铸 | B30: 46211 | C30: 0001254 | D30: LX0010-Y | E30: =VLOOKUP($D30,物料本月库存明細!$B:$J,2,0) -> T93-20 | F30: =VLOOKUP($D30,物料本月库存明細!$B:$J,5,0) -> PCS | G30: 14400 | J30: =VLOOKUP($D30,物料本月库存明細!$B:$J,9,0) -> 14400
A31: 绮丽 | B31: 46206 | C31: F26070316 | D31: LX00016-P | E31: =VLOOKUP($D31,物料本月库存明細!$B:$J,2,0) -> JK111-03机壳(无牙） | F31: =VLOOKUP($D31,物料本月库存明細!$B:$J,5,0) -> PCS | G31: 2 | H31: 素材不良退回2个 | J31: =VLOOKUP($D31,物料本月库存明細!$B:$J,9,0) -> 2
A32: 绮丽 | B32: 46206 | C32: F26070316 | D32: LX00016-DY | E32: =VLOOKUP($D32,物料本月库存明細!$B:$J,2,0) -> JK111-03机壳(无牙） | F32: =VLOOKUP($D32,物料本月库存明細!$B:$J,5,0) -> PCS | G32: 3283 | J32: =VLOOKUP($D32,物料本月库存明細!$B:$J,9,0) -> 0
A33: 绮丽 | B33: 46206 | C33: F26070316 | D33: LX00019-DY | E33: =VLOOKUP($D33,物料本月库存明細!$B:$J,2,0) -> T93-29 | F33: =VLOOKUP($D33,物料本月库存明細!$B:$J,5,0) -> PCS | G33: 3096 | J33: =VLOOKUP($D33,物料本月库存明細!$B:$J,9,0) -> 0
A34: 绮丽 | B34: 46207 | C34: F26070425 | D34: LX00025-DY | E34: =VLOOKUP($D34,物料本月库存明細!$B:$J,2,0) -> JK111-05机壳（无牙） | F34: =VLOOKUP($D34,物料本月库存明細!$B:$J,5,0) -> PCS | G34: 1456 | J34: =VLOOKUP($D34,物料本月库存明細!$B:$J,9,0) -> 5
A35: 绮丽 | B35: 46207 | C35: F26070425 | D35: LX00020-DY | E35: =VLOOKUP($D35,物料本月库存明細!$B:$J,2,0) -> T93-33 | F35: =VLOOKUP($D35,物料本月库存明細!$B:$J,5,0) -> PCS | G35: 3276 | J35: =VLOOKUP($D35,物料本月库存明細!$B:$J,9,0) -> 0
A36: 绮丽 | B36: 46207 | C36: F26070425 | D36: LX00019-DY | E36: =VLOOKUP($D36,物料本月库存明細!$B:$J,2,0) -> T93-29 | F36: =VLOOKUP($D36,物料本月库存明細!$B:$J,5,0) -> PCS | G36: 1728 | J36: =VLOOKUP($D36,物料本月库存明細!$B:$J,9,0) -> 0
A37: 绮丽 | B37: 46207 | C37: F26070426 | D37: LX00025-DY | E37: =VLOOKUP($D37,物料本月库存明細!$B:$J,2,0) -> JK111-05机壳（无牙） | F37: =VLOOKUP($D37,物料本月库存明細!$B:$J,5,0) -> PCS | G37: 5 | H37: 不良退回 | J37: =VLOOKUP($D37,物料本月库存明細!$B:$J,9,0) -> 5
A38: 绮丽 | B38: 46210 | C38: F26070701 | D38: LX00025-DY | E38: =VLOOKUP($D38,物料本月库存明細!$B:$J,2,0) -> JK111-05机壳（无牙） | F38: =VLOOKUP($D38,物料本月库存明細!$B:$J,5,0) -> PCS | G38: 1620 | J38: =VLOOKUP($D38,物料本月库存明細!$B:$J,9,0) -> 5
A39: 绮丽 | B39: 46210 | C39: F26070701 | D39: LX00019-DY | E39: =VLOOKUP($D39,物料本月库存明細!$B:$J,2,0) -> T93-29 | F39: =VLOOKUP($D39,物料本月库存明細!$B:$J,5,0) -> PCS | G39: 5293 | J39: =VLOOKUP($D39,物料本月库存明細!$B:$J,9,0) -> 0
A40: 麦凯良 | B40: 46211 | C40: 0006330 | D40: YL001-DM | E40: =VLOOKUP($D40,物料本月库存明細!$B:$J,2,0) -> 1A321W1M001-0A(EL-321W-GL04 铝壳） | F40: =VLOOKUP($D40,物料本月库存明細!$B:$J,5,0) -> PCS | G40: 800 | J40: =VLOOKUP($D40,物料本月库存明細!$B:$J,9,0) -> 2400
...

Sheet 半成品出库明细
A1: 厂商 | B1: 日 期 | C1: 单据编号 | D1: 料号 | E1: 机种名称 | F1: 单位 | G1: 数量 | H1: 备注 | J1: 本月库存
A2: 压铸 | B2: 46208 | C2: 0020148 | D2: RB002 | E2: =VLOOKUP($D2,物料本月库存明細!$B:$J,2,0) -> 扳手809轴套（500N轴套） | F2: =VLOOKUP($D2,物料本月库存明細!$B:$J,5,0) -> PCS | G2: 5250 | J2: =VLOOKUP($D2,物料本月库存明細!$B:$J,9,0) -> 0
A3: 压铸 | B3: 46208 | C3: 0020148 | D3: RB014 | E3: =VLOOKUP($D3,物料本月库存明細!$B:$J,2,0) -> 819/826轴套 | F3: =VLOOKUP($D3,物料本月库存明細!$B:$J,5,0) -> PCS | G3: 3780 | J3: =VLOOKUP($D3,物料本月库存明細!$B:$J,9,0) -> 0
A4: 麦凯良 | B4: 46208 | C4: 0002792 | D4: RB023-Y | E4: =VLOOKUP($D4,物料本月库存明細!$B:$J,2,0) -> 扳手828头壳 | F4: =VLOOKUP($D4,物料本月库存明細!$B:$J,5,0) -> PCS | G4: 210 | J4: =VLOOKUP($D4,物料本月库存明細!$B:$J,9,0) -> 0
A5: 压铸 | B5: 46209 | C5: 0020149 | D5: A | E5: =VLOOKUP($D5,物料本月库存明細!$B:$J,2,0) -> ADC12铝料 | F5: =VLOOKUP($D5,物料本月库存明細!$B:$J,5,0) -> KG | G5: =834.5+811.5 -> 1646 | J5: =VLOOKUP($D5,物料本月库存明細!$B:$J,9,0) -> 5820.5
A6: 锦宇树 | B6: 46209 | C6: 0002794 | D6: LX0010-P | E6: =VLOOKUP($D6,物料本月库存明細!$B:$J,2,0) -> T93-20 | F6: =VLOOKUP($D6,物料本月库存明細!$B:$J,5,0) -> PCS | G6: 14198 | J6: =VLOOKUP($D6,物料本月库存明細!$B:$J,9,0) -> 12480
A7: 锦宇树 | B7: 46209 | C7: 0002794 | D7: RB011-KQ | E7: =VLOOKUP($D7,物料本月库存明細!$B:$J,2,0) -> 扳手810头壳（无轴套） | F7: =VLOOKUP($D7,物料本月库存明細!$B:$J,5,0) -> PCS | G7: 1100 | J7: =VLOOKUP($D7,物料本月库存明細!$B:$J,9,0) -> 2132
A8: 锦宇树 | B8: 46209 | C8: 0002794 | D8: RB003-PW | E8: =VLOOKUP($D8,物料本月库存明細!$B:$J,2,0) -> 扳手809端盖 | F8: =VLOOKUP($D8,物料本月库存明細!$B:$J,5,0) -> PCS | G8: 10350 | J8: =VLOOKUP($D8,物料本月库存明細!$B:$J,9,0) -> 0
A9: 凤友 | B9: 46209 | C9: 0002673 | D9: RB027-M | E9: =VLOOKUP($D9,物料本月库存明細!$B:$J,2,0) -> 扳手810STK2头壳 | F9: =VLOOKUP($D9,物料本月库存明細!$B:$J,5,0) -> PCS | G9: 712 | J9: =VLOOKUP($D9,物料本月库存明細!$B:$J,9,0) -> 0
A10: 凤友 | B10: 46209 | C10: 0002673 | D10: HH0023-C | E10: =VLOOKUP($D10,物料本月库存明細!$B:$J,2,0) -> HH8513传导片 | F10: =VLOOKUP($D10,物料本月库存明細!$B:$J,5,0) -> PCS | G10: 6160 | J10: =VLOOKUP($D10,物料本月库存明細!$B:$J,9,0) -> 0
A11: 凤友 | B11: 46209 | C11: 0002673 | D11: HH0026-Y | E11: =VLOOKUP($D11,物料本月库存明細!$B:$J,2,0) -> 铝底座/8526 | F11: =VLOOKUP($D11,物料本月库存明細!$B:$J,5,0) -> PCS | G11: 8110 | J11: =VLOOKUP($D11,物料本月库存明細!$B:$J,9,0) -> 0
A12: 凤友 | B12: 46209 | C12: 0002673 | D12: HH0004-Y | E12: =VLOOKUP($D12,物料本月库存明細!$B:$J,2,0) -> 小金童铝连杆 | F12: =VLOOKUP($D12,物料本月库存明細!$B:$J,5,0) -> PCS | G12: 13300 | J12: =VLOOKUP($D12,物料本月库存明細!$B:$J,9,0) -> 0
A13: 锦拓 | B13: 46209 | C13: 0002793 | D13: LX0010-Y | E13: =VLOOKUP($D13,物料本月库存明細!$B:$J,2,0) -> T93-20 | F13: =VLOOKUP($D13,物料本月库存明細!$B:$J,5,0) -> PCS | G13: 12480 | J13: =VLOOKUP($D13,物料本月库存明細!$B:$J,9,0) -> 14400
A14: 锦拓 | B14: 46209 | C14: 0002793 | D14: RB024-Y | E14: =VLOOKUP($D14,物料本月库存明細!$B:$J,2,0) -> 扳手828端盖 | F14: =VLOOKUP($D14,物料本月库存明細!$B:$J,5,0) -> PCS | G14: 720 | J14: =VLOOKUP($D14,物料本月库存明細!$B:$J,9,0) -> 0
A15: 锦拓 | B15: 46209 | C15: 0002793 | D15: HH0028-C | E15: =VLOOKUP($D15,物料本月库存明細!$B:$J,2,0) -> 8527旋钮 | F15: =VLOOKUP($D15,物料本月库存明細!$B:$J,5,0) -> PCS | G15: 1064 | J15: =VLOOKUP($D15,物料本月库存明細!$B:$J,9,0) -> 0
A16: 报废 | B16: 46209 | C16: 0001456 | D16: RB027-KQ | E16: =VLOOKUP($D16,物料本月库存明細!$B:$J,2,0) -> 扳手810STK2头壳 | F16: =VLOOKUP($D16,物料本月库存明細!$B:$J,5,0) -> PCS | G16: 15 | J16: =VLOOKUP($D16,物料本月库存明細!$B:$J,9,0) -> 2215
A17: 全才 | B17: 46210 | C17: 0002795 | D17: HH0023-GY | E17: =VLOOKUP($D17,物料本月库存明細!$B:$J,2,0) -> HH8513传导片 | F17: =VLOOKUP($D17,物料本月库存明細!$B:$J,5,0) -> PCS | G17: 200 | J17: =VLOOKUP($D17,物料本月库存明細!$B:$J,9,0) -> -200
... A22: 麦凯良 | B22: 46210 | C22: 0002798 | D22: RB016-Y | E22: =VLOOKUP($D22,物料本月库存明細!$B:$J,2,0) -> 826头壳（含轴套） | F22: =VLOOKUP($D22,物料本月库存明細!$B:$J,5,0) -> PCS | G22: 1800 | J22: =VLOOKUP($D22,物料本月库存明細!$B:$J,9,0) -> 0
A23: 金恒 | B23: 46210 | C23: 0002799 | D23: DW003-PG | E23: =VLOOKUP($D23,物料本月库存明細!$B:$J,2,0) -> W2805-850N头壳 | F23: =VLOOKUP($D23,物料本月库存明細!$B:$J,5,0) -> KG | G23: 50 | H23: 验证品 | J23: =VLOOKUP($D23,物料本月库存明細!$B:$J,9,0) -> 0
A24: 金恒 | B24: 46210 | C24: 0002799 | D24: DW004-PG | E24: =VLOOKUP($D24,物料本月库存明細!$B:$J,2,0) -> W2805-850N端盖 | F24: =VLOOKUP($D24,物料本月库存明細!$B:$J,5,0) -> KG | G24: 50 | H24: 验证品 | J24: =VLOOKUP($D24,物料本月库存明細!$B:$J,9,0) -> 0
A25: 锦拓 | B25: 46210 | C25: 0002800 | D25: LX0010-Y | E25: =VLOOKUP($D25,物料本月库存明細!$B:$J,2,0) -> T93-20 | F25: =VLOOKUP($D25,物料本月库存明細!$B:$J,5,0) -> PCS | G25: 9600 | J25: =VLOOKUP($D25,物料本月库存明細!$B:$J,9,0) -> 14400
A26: 压铸 | B26: 46211 | C26: 0020150 | D26: A | E26: =VLOOKUP($D26,物料本月库存明細!$B:$J,2,0) -> ADC12铝料 | F26: =VLOOKUP($D26,物料本月库存明細!$B:$J,5,0) -> KG | G26: 837 | J26: =VLOOKUP($D26,物料本月库存明細!$B:$J,9,0) -> 5820.5
A27: 压铸 | B27: 46211 | C27: 0020150 | D27: A | E27: =VLOOKUP($D27,物料本月库存明細!$B:$J,2,0) -> ADC12铝料 | F27: =VLOOKUP($D27,物料本月库存明細!$B:$J,5,0) -> KG | G27: 829.5 | J27: =VLOOKUP($D27,物料本月库存明細!$B:$J,9,0) -> 5820.5
A28: 压铸 | B28: 46211 | C28: 0020150 | D28: A | E28: =VLOOKUP($D28,物料本月库存明細!$B:$J,2,0) -> ADC12铝料 | F28: =VLOOKUP($D28,物料本月库存明細!$B:$J,5,0) -> KG | G28: 847 | J28: =VLOOKUP($D28,物料本月库存明細!$B:$J,9,0) -> 5820.5
A29: 压铸 | B29: 46211 | C29: 0020150 | D29: A | E29: =VLOOKUP($D29,物料本月库存明細!$B:$J,2,0) -> ADC12铝料 | F29: =VLOOKUP($D29,物料本月库存明細!$B:$J,5,0) -> KG | G29: 845 | J29: =VLOOKUP($D29,物料本月库存明細!$B:$J,9,0) -> 5820.5
A30: 喜来来 | B30: 46211 | C30: 0002801 | D30: OFG006-GY | E30: =VLOOKUP($D30,物料本月库存明細!$B:$J,2,0) -> （YC013600303900）MS11前壳 | F30: =VLOOKUP($D30,物料本月库存明細!$B:$J,5,0) -> PCS | G30: 13460 | J30: =VLOOKUP($D30,物料本月库存明細!$B:$J,9,0) -> 0
A31: 麦凯良 | B31: 46211 | C31: 0000904 | D31: YL001-DM | E31: =VLOOKUP($D31,物料本月库存明細!$B:$J,2,0) -> 1A321W1M001-0A(EL-321W-GL04 铝壳） | F31: =VLOOKUP($D31,物料本月库存明細!$B:$J,5,0) -> PCS | G31: 1600 | H31: 打磨不良 | J31: =VLOOKUP($D31,物料本月库存明細!$B:$J,9,0) -> 2400
A32: 麦凯良 | B32: 46211 | C32: 0002802 | D32: YL001-Y | E32: =VLOOKUP($D32,物料本月库存明細!$B:$J,2,0) -> 1A321W1M001-0A(EL-321W-GL04 铝壳） | F32: =VLOOKUP($D32,物料本月库存明細!$B:$J,5,0) -> PCS | G32: 2400 | J32: =VLOOKUP($D32,物料本月库存明細!$B:$J,9,0) -> 0
A33: 麦凯良 | B33: 46211 | C33: 0002802 | D33: RB004-Y | E33: =VLOOKUP($D33,物料本月库存明細!$B:$J,2,0) -> 起子机2108-W头壳（230N头壳无轴套） | F33: =VLOOKUP($D33,物料本月库存明細!$B:$J,5,0) -> PCS | G33: 2395 | H33: 设变后 | J33: =VLOOKUP($D33,物料本月库存明細!$B:$J,9,0) -> 0
A34: 瑞联 | B34: 46211 | C34: 0002803 | D34: LX00025-DY | E34: =VLOOKUP($D34,物料本月库存明細!$B:$J,2,0) -> JK111-05机壳（无牙） | F34: =VLOOKUP($D34,物料本月库存明細!$B:$J,5,0) -> PCS | G34: 3076 | J34: =VLOOKUP($D34,物料本月库存明細!$B:$J,9,0) -> 5
A35: 瑞联 | B35: 46211 | C35: 0002803 | D35: LX00020-DY | E35: =VLOOKUP($D35,物料本月库存明細!$B:$J,2,0) -> T93-33 | F35: =VLOOKUP($D35,物料本月库存明細!$B:$J,5,0) -> PCS | G35: 3276 | J35: =VLOOKUP($D35,物料本月库存明細!$B:$J,9,0) -> 0
A36: 瑞联 | B36: 46211 | C36: 0002803 | D36: LX00019-DY | E36: =VLOOKUP($D36,物料本月库存明細!$B:$J,2,0) -> T93-29 | F36: =VLOOKUP($D36,物料本月库存明細!$B:$J,5,0) -> PCS | G36: 10117 | J36: =VLOOKUP($D36,物料本月库存明細!$B:$J,9,0) -> 0
A37: 瑞联 | B37: 46211 | C37: 0002803 | D37: LX00016-DY | E37: =VLOOKUP($D37,物料本月库存明細!$B:$J,2,0) -> JK111-03机壳(无牙） | F37: =VLOOKUP($D37,物料本月库存明細!$B:$J,5,0) -> PCS | G37: 3283 | J37: =VLOOKUP($D37,物料本月库存明細!$B:$J,9,0) -> 0
A38: 同齐力 | B38: 46211 | C38: 0002804 | D38: YL001-DM | E38: =VLOOKUP($D38,物料本月库存明細!$B:$J,2,0) -> 1A321W1M001-0A(EL-321W-GL04 铝壳） | F38: =VLOOKUP($D38,物料本月库存明細!$B:$J,5,0) -> PCS | G38: 1600 | J38: =VLOOKUP($D38,物料本月库存明細!$B:$J,9,0) -> 2400
A39: 同齐力 | B39: 46211 | C39: 0002804 | D39: HH0004-GY | E39: =VLOOKUP($D39,物料本月库存明細!$B:$J,2,0) -> 小金童铝连杆 | F39: =VLOOKUP($D39,物料本月库存明細!$B:$J,5,0) -> PCS | G39: 6600 | J39: =VLOOKUP($D39,物料本月库存明細!$B:$J,9,0) -> 0
A40: 同齐力 | B40: 46211 | C40: 0002804 | D40: RB034-PW | E40: =VLOOKUP($D40,物料本月库存明細!$B:$J,2,0) -> 黄油枪HY01A齿轮箱 | F40: =VLOOKUP($D40,物料本月库存明細!$B:$J,5,0) -> PCS | G40: 147 | J40: =VLOOKUP($D40,物料本月库存明細!$B:$J,9,0) -> 37
A41: 义恒谱 | B41: 46211 | C41: 0002805 | D41: LX00020-C | E41: =VLOOKUP($D41,物料本月库存明細!$B:$J,2,0) -> T93-33 | F41: =VLOOKUP($D41,物料本月库存明細!$B:$J,5,0) -> PCS | G41: 1080 | J41: =VLOOKUP($D41,物料本月库存明細!$B:$J,9,0) -> 0
A42: 锦宇树 | B42: 46211 | C42: 0002807 | D42: RB012-KQ | E42: =VLOOKUP($D42,物料本月库存明細!$B:$J,2,0) -> 扳手810端盖 | F42: =VLOOKUP($D42,物料本月库存明細!$B:$J,5,0) -> PCS | G42: 2988 | J42: =VLOOKUP($D42,物料本月库存明細!$B:$J,9,0) -> 3600
A43: 锦宇树 | B43: 46211 | C43: 0002807 | D43: RB027-KQ | E43: =VLOOKUP($D43,物料本月库存明細!$B:$J,2,0) -> 扳手810STK2头壳 | F43: =VLOOKUP($D43,物料本月库存明細!$B:$J,5,0) -> PCS | G43: 3013 | J43: =VLOOKUP($D43,物料本月库存明細!$B:$J,9,0) -> 2215
A44: 巧手 | B44: 46211 | C44: 0002808 | D44: YL001-CNC | E44: =VLOOKUP($D44,物料本月库存明細!$B:$J,2,0) -> 1A321W1M001-0A(EL-321W-GL04 铝壳） | F44: =VLOOKUP($D44,物料本月库存明細!$B:$J,5,0) -> PCS | G44: 1760 | J44: =VLOOKUP($D44,物料本月库存明細!$B:$J,9,0) -> 0
...

Sheet 物料本月库存明細
A1: 序号 | B1: 料号 | C1: 品名/料号 | D1: 客户 | E1: 备注工艺 | F1: 单位 | G1: 月初结存 | H1: 本月入库 | I1: 本月出库 | J1: 本月结存 | L1: 成品段
A2: 1 | B2: ZM0001-Y | C2: H56上盖 | D2: 纵目 | E2: 压铸 | F2: PCS | G2: =SUMIF(物料月初库存!$C$3:$C$303,$B2,物料月初库存!$F$3:$F$303) -> 0 | H2: =SUMIF(半成品入库明细!$D$2:$D$650,$B2,半成品入库明细!$G$2:$G$650) -> 0 | I2: =SUMIF(半成品出库明细!$D$2:$D$558,$B2,半成品出库明细!$G$2:$G$2) -> 0 | J2: =G2+H2-I2 -> 0
A3: 2 | B3: ZM0001-ZY | C3: H56上盖 | D3: 纵目 | E3: 振研 | F3: PCS | G3: =SUMIF(物料月初库存!$C$3:$C$303,$B3,物料月初库存!$F$3:$F$303) -> 0 | H3: =SUMIF(半成品入库明细!$D$2:$D$650,$B3,半成品入库明细!$G$2:$G$650) -> 0 | I3: =SUMIF(半成品出库明细!$D$2:$D$558,$B3,半成品出库明细!$G$2:$G$2) -> 0 | J3: =G3+H3-I3 -> 0 | K3: 喜来来
A4: 3 | B4: ZM0001-P | C4: H56上盖 | D4: 纵目 | E4: 皮膜 | F4: PCS | G4: =SUMIF(物料月初库存!$C$3:$C$303,$B4,物料月初库存!$F$3:$F$303) -> 0 | H4: =SUMIF(半成品入库明细!$D$2:$D$650,$B4,半成品入库明细!$G$2:$G$650) -> 0 | I4: =SUMIF(半成品出库明细!$D$2:$D$558,$B4,半成品出库明细!$G$2:$G$2) -> 0 | J4: =G4+H4-I4 -> 0 | K4: 巧手 | L4: 成品
A5: 4 | B5: ZM0002-Y | C5: H56下盖 | D5: 纵目 | E5: 压铸 | F5: PCS | G5: =SUMIF(物料月初库存!$C$3:$C$303,$B5,物料月初库存!$F$3:$F$303) -> 0 | H5: =SUMIF(半成品入库明细!$D$2:$D$650,$B5,半成品入库明细!$G$2:$G$650) -> 0 | I5: =SUMIF(半成品出库明细!$D$2:$D$558,$B5,半成品出库明细!$G$2:$G$2) -> 0 | J5: =G5+H5-I5 -> 0
A6: 5 | B6: ZM0002-ZY | C6: H56下盖 | D6: 纵目 | E6: 振研 | F6: PCS | G6: =SUMIF(物料月初库存!$C$3:$C$303,$B6,物料月初库存!$F$3:$F$303) -> 0 | H6: =SUMIF(半成品入库明细!$D$2:$D$650,$B6,半成品入库明细!$G$2:$G$650) -> 0 | I6: =SUMIF(半成品出库明细!$D$2:$D$558,$B6,半成品出库明细!$G$2:$G$2) -> 0 | J6: =G6+H6-I6 -> 0 | K6: 喜来来
A7: 6 | B7: ZM0002-P | C7: H56下盖 | D7: 纵目 | E7: 皮膜 | F7: PCS | G7: =SUMIF(物料月初库存!$C$3:$C$303,$B7,物料月初库存!$F$3:$F$303) -> 0 | H7: =SUMIF(半成品入库明细!$D$2:$D$650,$B7,半成品入库明细!$G$2:$G$650) -> 0 | I7: =SUMIF(半成品出库明细!$D$2:$D$558,$B7,半成品出库明细!$G$2:$G$2) -> 0 | J7: =G7+H7-I7 -> 0 | K7: 巧手 | L7: 成品
A8: 7 | B8: ZM0003-Y | C8: 金康X1上盖 | D8: 纵目 | E8: 压铸 | F8: PCS | G8: =SUMIF(物料月初库存!$C$3:$C$303,$B8,物料月初库存!$F$3:$F$303) -> 0 | H8: =SUMIF(半成品入库明细!$D$2:$D$650,$B8,半成品入库明细!$G$2:$G$650) -> 0 | I8: =SUMIF(半成品出库明细!$D$2:$D$558,$B8,半成品出库明细!$G$2:$G$2) -> 0 | J8: =G8+H8-I8 -> 0
A9: 8 | B9: ZM0003-ZY | C9: 金康X1上盖 | D9: 纵目 | E9: 振研 | F9: PCS | G9: =SUMIF(物料月初库存!$C$3:$C$303,$B9,物料月初库存!$F$3:$F$303) -> 0 | H9: =SUMIF(半成品入库明细!$D$2:$D$650,$B9,半成品入库明细!$G$2:$G$650) -> 0 | I9: =SUMIF(半成品出库明细!$D$2:$D$558,$B9,半成品出库明细!$G$2:$G$2) -> 0 | J9: =G9+H9-I9 -> 0 | K9: 鑫宝泰/志远,喜来来 | L9: 成品
A10: 9 | B10: ZM0004-Y | C10: 金康X1下盖 | D10: 纵目 | E10: 压铸 | F10: PCS | G10: =SUMIF(物料月初库存!$C$3:$C$303,$B10,物料月初库存!$F$3:$F$303) -> 0 | H10: =SUMIF(半成品入库明细!$D$2:$D$650,$B10,半成品入库明细!$G$2:$G$650) -> 0 | I10: =SUMIF(半成品出库明细!$D$2:$D$558,$B10,半成品出库明细!$G$2:$G$2) -> 0 | J10: =G10+H10-I10 -> 0
A11: 10 | B11: ZM0004-ZY | C11: 金康X1下盖 | D11: 纵目 | E11: 振研 | F11: PCS | G11: =SUMIF(物料月初库存!$C$3:$C$303,$B11,物料月初库存!$F$3:$F$303) -> 0 | H11: =SUMIF(半成品入库明细!$D$2:$D$650,$B11,半成品入库明细!$G$2:$G$650) -> 0 | I11: =SUMIF(半成品出库明细!$D$2:$D$558,$B11,半成品出库明细!$G$2:$G$2) -> 0 | J11: =G11+H11-I11 -> 0 | K11: 鑫宝泰/志远,喜来来 | L11: 成品
A12: 11 | B12: ZM0005-Y | C12: 金康F1上盖 | D12: 纵目 | E12: 压铸 | F12: PCS | G12: =SUMIF(物料月初库存!$C$3:$C$303,$B12,物料月初库存!$F$3:$F$303) -> 0 | H12: =SUMIF(半成品入库明细!$D$2:$D$650,$B12,半成品入库明细!$G$2:$G$650) -> 0 | I12: =SUMIF(半成品出库明细!$D$2:$D$558,$B12,半成品出库明细!$G$2:$G$2) -> 0 | J12: =G12+H12-I12 -> 0
A13: 12 | B13: ZM0005-ZY | C13: 金康F1上盖 | D13: 纵目 | E13: 振研 | F13: PCS | G13: =SUMIF(物料月初库存!$C$3:$C$303,$B13,物料月初库存!$F$3:$F$303) -> 0 | H13: =SUMIF(半成品入库明细!$D$2:$D$650,$B13,半成品入库明细!$G$2:$G$650) -> 0 | I13: =SUMIF(半成品出库明细!$D$2:$D$558,$B13,半成品出库明细!$G$2:$G$2) -> 0 | J13: =G13+H13-I13 -> 0 | K13: 喜来来 成品 | L13: 成品
A14: 13 | B14: ZM0006-Y | C14: C385上盖 | D14: 纵目 | E14: 压铸 | F14: PCS | G14: =SUMIF(物料月初库存!$C$3:$C$303,$B14,物料月初库存!$F$3:$F$303) -> 0 | H14: =SUMIF(半成品入库明细!$D$2:$D$650,$B14,半成品入库明细!$G$2:$G$650) -> 0 | I14: =SUMIF(半成品出库明细!$D$2:$D$558,$B14,半成品出库明细!$G$2:$G$2) -> 0 | J14: =G14+H14-I14 -> 0
A15: 14 | B15: ZM0006-M | C15: C385上盖 | D15: 纵目 | E15: 毛边打磨/过砂 | F15: PCS | G15: =SUMIF(物料月初库存!$C$3:$C$303,$B15,物料月初库存!$F$3:$F$303) -> 0 | H15: =SUMIF(半成品入库明细!$D$2:$D$650,$B15,半成品入库明细!$G$2:$G$650) -> 0 | I15: =SUMIF(半成品出库明细!$D$2:$D$558,$B15,半成品出库明细!$G$2:$G$2) -> 0 | J15: =G15+H15-I15 -> 0 | K15: 日安升
A16: 15 | B16: ZM0006-P | C16: C385上盖 | D16: 纵目 | E16: 抛丸 | F16: PCS | G16: =SUMIF(物料月初库存!$C$3:$C$303,$B16,物料月初库存!$F$3:$F$303) -> 0 | H16: =SUMIF(半成品入库明细!$D$2:$D$650,$B16,半成品入库明细!$G$2:$G$650) -> 0 | I16: =SUMIF(半成品出库明细!$D$2:$D$558,$B16,半成品出库明细!$G$2:$G$2) -> 0 | J16: =G16+H16-I16 -> 0 | K16: 锦拓
A17: 16 | B17: ZM0006-D(P) | C17: C385上盖 | D17: 纵目 | E17: 皮膜（钝化） | F17: PCS | G17: =SUMIF(物料月初库存!$C$3:$C$303,$B17,物料月初库存!$F$3:$F$303) -> 0 | H17: =SUMIF(半成品入库明细!$D$2:$D$650,$B17,半成品入库明细!$G$2:$G$650) -> 0 | I17: =SUMIF(半成品出库明细!$D$2:$D$558,$B17,半成品出库明细!$G$2:$G$2) -> 0 | J17: =G17+H17-I17 -> 0 | K17: 巧手 | L17: 成品
A18: 17 | B18: ZM0007-Y | C18: C385下盖 | D18: 纵目 | E18: 压铸 | F18: PCS | G18: =SUMIF(物料月初库存!$C$3:$C$303,$B18,物料月初库存!$F$3:$F$303) -> 0 | H18: =SUMIF(半成品入库明细!$D$2:$D$650,$B18,半成品入库明细!$G$2:$G$650) -> 0 | I18: =SUMIF(半成品出库明细!$D$2:$D$558,$B18,半成品出库明细!$G$2:$G$2) -> 0 | J18: =G18+H18-I18 -> 0
A19: 19 | B19: ZM0007-P | C19: C385下盖 | D19: 纵目 | E19: 抛丸 | F19: PCS | G19: =SUMIF(物料月初库存!$C$3:$C$303,$B19,物料月初库存!$F$3:$F$303) -> 0 | H19: =SUMIF(半成品入库明细!$D$2:$D$650,$B19,半成品入库明细!$G$2:$G$650) -> 0 | I19: =SUMIF(半成品出库明细!$D$2:$D$558,$B19,半成品出库明细!$G$2:$G$2) -> 0 | J19: =G19+H19-I19 -> 0 | K19: 锦拓
A20: 20 | B20: ZM0007-D(P) | C20: C385下盖 | D20: 纵目 | E20: 皮膜（钝化） | F20: PCS | G20: =SUMIF(物料月初库存!$C$3:$C$303,$B20,物料月初库存!$F$3:$F$303) -> 0 | H20: =SUMIF(半成品入库明细!$D$2:$D$650,$B20,半成品入库明细!$G$2:$G$650) -> 0 | I20: =SUMIF(半成品出库明细!$D$2:$D$558,$B20,半成品出库明细!$G$2:$G$2) -> 0 | J20: =G20+H20-I20 -> 0 | K20: 巧手 | L20: 成品
A21: 21 | B21: ZM0008-Y | C21: C001_APA主机上盖 | D21: 纵目 | E21: 压铸 | F21: PCS | G21: =SUMIF(物料月初库存!$C$3:$C$303,$B21,物料月初库存!$F$3:$F$303) -> 0 | H21: =SUMIF(半成品入库明细!$D$2:$D$650,$B21,半成品入库明细!$G$2:$G$650) -> 0 | I21: =SUMIF(半成品出库明细!$D$2:$D$558,$B21,半成品出库明细!$G$2:$G$2) -> 0 | J21: =G21+H21-I21 -> 0
A22: 22 | B22: ZM0008-M | C22: C001_APA主机上盖 | D22: 纵目 | E22: 毛边 | F22: PCS | G22: =SUMIF(物料月初库存!$C$3:$C$303,$B22,物料月初库存!$F$3:$F$303) -> 0 | H22: =SUMIF(半成品入库明细!$D$2:$D$650,$B22,半成品入库明细!$G$2:$G$650) -> 0 | I22: =SUMIF(半成品出库明细!$D$2:$D$558,$B22,半成品出库明细!$G$2:$G$2) -> 0 | J22: =G22+H22-I22 -> 0 | K22: 厂内毛边，邦宇
A23: 23 | B23: ZM0008-ZY | C23: C001_APA主机上盖 | D23: 纵目 | E23: 振研 | F23: PCS | G23: =SUMIF(物料月初库存!$C$3:$C$303,$B23,物料月初库存!$F$3:$F$303) -> 0 | H23: =SUMIF(半成品入库明细!$D$2:$D$650,$B23,半成品入库明细!$G$2:$G$650) -> 0 | I23: =SUMIF(半成品出库明细!$D$2:$D$558,$B23,半成品出库明细!$G$2:$G$2) -> 0 | J23: =G23+H23-I23 -> 0 | K23: 喜来来 | L23: 成品
B24: ZM0008-QX | C24: C001_APA主机上盖 | D24: 纵目 | E24: 清洗 | F24: PCS | G24: =SUMIF(物料月初库存!$C$3:$C$303,$B24,物料月初库存!$F$3:$F$303) -> 0 | H24: =SUMIF(半成品入库明细!$D$2:$D$650,$B24,半成品入库明细!$G$2:$G$650) -> 0 | I24: =SUMIF(半成品出库明细!$D$2:$D$558,$B24,半成品出库明细!$G$2:$G$2) -> 0 | J24: =G24+H24-I24 -> 0 | K24: 临时工艺,巧手
A25: 24 | B25: ZM0009-Y | C25: C001_APA主机下盖 | D25: 纵目 | E25: 压铸 | F25: PCS | G25: =SUMIF(物料月初库存!$C$3:$C$303,$B25,物料月初库存!$F$3:$F$303) -> 0 | H25: =SUMIF(半成品入库明细!$D$2:$D$650,$B25,半成品入库明细!$G$2:$G$650) -> 0 | I25: =SUMIF(半成品出库明细!$D$2:$D$558,$B25,半成品出库明细!$G$2:$G$2) -> 0 | J25: =G25+H25-I25 -> 0
A26: 25 | B26: ZM0009-M | C26: C001_APA主机下盖 | D26: 纵目 | E26: 毛边 | F26: PCS | G26: =SUMIF(物料月初库存!$C$3:$C$303,$B26,物料月初库存!$F$3:$F$303) -> 0 | H26: =SUMIF(半成品入库明细!$D$2:$D$650,$B26,半成品入库明细!$G$2:$G$650) -> 0 | I26: =SUMIF(半成品出库明细!$D$2:$D$558,$B26,半成品出库明细!$G$2:$G$2) -> 0 | J26: =G26+H26-I26 -> 0 | K26: 厂内毛边
A27: 26 | B27: ZM0009-ZY | C27: C001_APA主机下盖 | D27: 纵目 | E27: 振研 | F27: PCS | G27: =SUMIF(物料月初库存!$C$3:$C$303,$B27,物料月初库存!$F$3:$F$303) -> 0 | H27: =SUMIF(半成品入库明细!$D$2:$D$650,$B27,半成品入库明细!$G$2:$G$650) -> 0 | I27: =SUMIF(半成品出库明细!$D$2:$D$558,$B27,半成品出库明细!$G$2:$G$2) -> 0 | J27: =G27+H27-I27 -> 0 | K27: 喜来来 | L27: 成品
A28: 27 | B28: ZM001-Y | C28: P-3 | D28: 卓民 | E28: 压铸 | F28: PCS | G28: =SUMIF(物料月初库存!$C$3:$C$303,$B28,物料月初库存!$F$3:$F$303) -> 0 | H28: =SUMIF(半成品入库明细!$D$2:$D$650,$B28,半成品入库明细!$G$2:$G$650) -> 0 | I28: =SUMIF(半成品出库明细!$D$2:$D$558,$B28,半成品出库明细!$G$2:$G$2) -> 0 | J28: =G28+H28-I28 -> 0
A29: 28 | B29: ZM001-Z | C29: P-3 | D29: 卓民 | E29: 钻孔/攻牙/倒角 | F29: PCS | G29: =SUMIF(物料月初库存!$C$3:$C$303,$B29,物料月初库存!$F$3:$F$303) -> 0 | H29: =SUMIF(半成品入库明细!$D$2:$D$650,$B29,半成品入库明细!$G$2:$G$650) -> 0 | I29: =SUMIF(半成品出库明细!$D$2:$D$558,$B29,半成品出库明细!$G$2:$G$2) -> 0 | J29: =G29+H29-I29 -> 0
A30: 29 | B30: ZM001-M | C30: P-3 | D30: 卓民 | E30: 铆钉 | F30: PCS | G30: =SUMIF(物料月初库存!$C$3:$C$303,$B30,物料月初库存!$F$3:$F$303) -> 0 | H30: =SUMIF(半成品入库明细!$D$2:$D$650,$B30,半成品入库明细!$G$2:$G$650) -> 0 | I30: =SUMIF(半成品出库明细!$D$2:$D$558,$B30,半成品出库明细!$G$2:$G$2) -> 0 | J30: =G30+H30-I30 -> 0
A31: 30 | B31: ZM001-B | C31: P-3 | D31: 卓民 | E31: 毛边/打磨 | F31: PCS | G31: =SUMIF(物料月初库存!$C$3:$C$303,$B31,物料月初库存!$F$3:$F$303) -> 0 | H31: =SUMIF(半成品入库明细!$D$2:$D$650,$B31,半成品入库明细!$G$2:$G$650) -> 0 | I31: =SUMIF(半成品出库明细!$D$2:$D$558,$B31,半成品出库明细!$G$2:$G$2) -> 0 | J31: =G31+H31-I31 -> 0
A32: 31 | B32: ZM001-K | C32: P-3 | D32: 卓民 | E32: 烤漆 | F32: PCS | G32: =SUMIF(物料月初库存!$C$3:$C$303,$B32,物料月初库存!$F$3:$F$303) -> 0 | H32: =SUMIF(半成品入库明细!$D$2:$D$650,$B32,半成品入库明细!$G$2:$G$650) -> 0 | I32: =SUMIF(半成品出库明细!$D$2:$D$558,$B32,半成品出库明细!$G$2:$G$2) -> 0 | J32: =G32+H32-I32 -> 0
A33: 32 | B33: ZM002-Y | C33: S-3 | D33: 卓民 | E33: 压铸 | F33: PCS | G33: =SUMIF(物料月初库存!$C$3:$C$303,$B33,物料月初库存!$F$3:$F$303) -> 0 | H33: =SUMIF(半成品入库明细!$D$2:$D$650,$B33,半成品入库明细!$G$2:$G$650) -> 0 | I33: =SUMIF(半成品出库明细!$D$2:$D$558,$B33,半成品出库明细!$G$2:$G$2) -> 0 | J33: =G33+H33-I33 -> 0
A34: 33 | B34: ZM002-B | C34: S-3 | D34: 卓民 | E34: 毛边/打磨 | F34: PCS | G34: =SUMIF(物料月初库存!$C$3:$C$303,$B34,物料月初库存!$F$3:$F$303) -> 0 | H34: =SUMIF(半成品入库明细!$D$2:$D$650,$B34,半成品入库明细!$G$2:$G$650) -> 0 | I34: =SUMIF(半成品出库明细!$D$2:$D$558,$B34,半成品出库明细!$G$2:$G$2) -> 0 | J34: =G34+H34-I34 -> 0
A35: 34 | B35: ZM002-K | C35: S-3 | D35: 卓民 | E35: 烤漆 | F35: PCS | G35: =SUMIF(物料月初库存!$C$3:$C$303,$B35,物料月初库存!$F$3:$F$303) -> 0 | H35: =SUMIF(半成品入库明细!$D$2:$D$650,$B35,半成品入库明细!$G$2:$G$650) -> 0 | I35: =SUMIF(半成品出库明细!$D$2:$D$558,$B35,半成品出库明细!$G$2:$G$2) -> 0 | J35: =G35+H35-I35 -> 0
A36: 35 | B36: ZM003-Y | C36: 61-55N05G001 | D36: 卓民 | E36: 压铸 | F36: PCS | G36: =SUMIF(物料月初库存!$C$3:$C$303,$B36,物料月初库存!$F$3:$F$303) -> 0 | H36: =SUMIF(半成品入库明细!$D$2:$D$650,$B36,半成品入库明细!$G$2:$G$650) -> 0 | I36: =SUMIF(半成品出库明细!$D$2:$D$558,$B36,半成品出库明细!$G$2:$G$2) -> 0 | J36: =G36+H36-I36 -> 0
A37: 36 | B37: ZM003-M/P | C37: 61-55N05G001 | D37: 卓民 | E37: 毛边/过砂 | F37: PCS | G37: =SUMIF(物料月初库存!$C$3:$C$303,$B37,物料月初库存!$F$3:$F$303) -> 0 | H37: =SUMIF(半成品入库明细!$D$2:$D$650,$B37,半成品入库明细!$G$2:$G$650) -> 0 | I37: =SUMIF(半成品出库明细!$D$2:$D$558,$B37,半成品出库明细!$G$2:$G$2) -> 0 | J37: =G37+H37-I37 -> 0
A38: 37 | B38: ZM003-K | C38: 61-55N05G001 | D38: 卓民 | E38: 烤漆 | F38: PCS | G38: =SUMIF(物料月初库存!$C$3:$C$303,$B38,物料月初库存!$F$3:$F$303) -> 0 | H38: =SUMIF(半成品入库明细!$D$2:$D$650,$B38,半成品入库明细!$G$2:$G$650) -> 0 | I38: =SUMIF(半成品出库明细!$D$2:$D$558,$B38,半成品出库明细!$G$2:$G$2) -> 0 | J38: =G38+H38-I38 -> 0
A39: 38 | B39: ZM003-G | C39: 61-55N05G001 | D39: 卓民 | E39: 攻牙 | F39: PCS | G39: =SUMIF(物料月初库存!$C$3:$C$303,$B39,物料月初库存!$F$3:$F$303) -> 0 | H39: =SUMIF(半成品入库明细!$D$2:$D$650,$B39,半成品入库明细!$G$2:$G$650) -> 0 | I39: =SUMIF(半成品出库明细!$D$2:$D$558,$B39,半成品出库明细!$G$2:$G$2) -> 0 | J39: =G39+H39-I39 -> 0
... A66: 65 | B66: YS002-Y | C66: AP31主机上盖（360上盖） | D66: 铱斯 | E66: 压铸 | F66: PCS | G66: =SUMIF(物料月初库存!$C$3:$C$303,$B66,物料月初库存!$F$3:$F$303) -> 0 | H66: =SUMIF(半成品入库明细!$D$2:$D$650,$B66,半成品入库明细!$G$2:$G$650) -> 0 | I66: =SUMIF(半成品出库明细!$D$2:$D$558,$B66,半成品出库明细!$G$2:$G$2) -> 0 | J66: =G66+H66-I66 -> 0
...
