Workbook
Name 料號: [1]保稅物料庫存明細!$B$1:$B$65536
Name 類別: #REF!
Name 單位: #REF!

Sheet 成品月初库存
D1: 7月成品
A2: 序号 | B2: 盘点日期 | C2: 料号 | D2: 机种名称 | E2: 单位 | F2: 数量 | G2: 备注 | H2: 本月库存 | I2: 实际数量
B3: 2026.7.6盘点 | D3: =VLOOKUP($C3,成品本月库存!$B:$J,2,0) -> #N/A | E3: =VLOOKUP($C3,成品本月库存!$B:$J,5,0) -> #N/A | H3: =VLOOKUP($C3,成品本月库存!$B:$J,9,0) -> #N/A
C4: YS002 | D4: =VLOOKUP($C4,成品本月库存!$B:$J,2,0) -> AP31主机上盖(360上盖) | E4: =VLOOKUP($C4,成品本月库存!$B:$J,5,0) -> PCS | F4: 2819 | H4: =VLOOKUP($C4,成品本月库存!$B:$J,9,0) -> 2819
C5: YS001 | D5: =VLOOKUP($C5,成品本月库存!$B:$J,2,0) -> AP31主机下盖(360下盖) | E5: =VLOOKUP($C5,成品本月库存!$B:$J,5,0) -> PCS | F5: 866 | H5: =VLOOKUP($C5,成品本月库存!$B:$J,9,0) -> 866
C6: YS003 | D6: =VLOOKUP($C6,成品本月库存!$B:$J,2,0) -> AS23主机上盖 | E6: =VLOOKUP($C6,成品本月库存!$B:$J,5,0) -> PCS | F6: 115 | H6: =VLOOKUP($C6,成品本月库存!$B:$J,9,0) -> 115
C7: YS004 | D7: =VLOOKUP($C7,成品本月库存!$B:$J,2,0) -> AS23主机下盖 | E7: =VLOOKUP($C7,成品本月库存!$B:$J,5,0) -> PCS | F7: 331 | H7: =VLOOKUP($C7,成品本月库存!$B:$J,9,0) -> 331
C8: XFT002 | D8: =VLOOKUP($C8,成品本月库存!$B:$J,2,0) -> 0008 | E8: =VLOOKUP($C8,成品本月库存!$B:$J,5,0) -> PCS | F8: 6097 | H8: =VLOOKUP($C8,成品本月库存!$B:$J,9,0) -> 6097
C9: XFT003 | D9: =VLOOKUP($C9,成品本月库存!$B:$J,2,0) -> 0009中框 | E9: =VLOOKUP($C9,成品本月库存!$B:$J,5,0) -> PCS | F9: 21816 | H9: =VLOOKUP($C9,成品本月库存!$B:$J,9,0) -> 22323
C10: XFT003 | D10: 0009中框 | F10: =80+427 -> 507 | G10: 烤漆不良
C11: XFT004 | D11: =VLOOKUP($C11,成品本月库存!$B:$J,2,0) -> DBC1481L1 | E11: =VLOOKUP($C11,成品本月库存!$B:$J,5,0) -> PCS | F11: 2424 | H11: =VLOOKUP($C11,成品本月库存!$B:$J,9,0) -> 2424
C12: XFT005 | D12: =VLOOKUP($C12,成品本月库存!$B:$J,2,0) -> DBC1480L1 | E12: =VLOOKUP($C12,成品本月库存!$B:$J,5,0) -> PCS | F12: 270 | H12: =VLOOKUP($C12,成品本月库存!$B:$J,9,0) -> 270
C13: XFT007 | D13: =VLOOKUP($C13,成品本月库存!$B:$J,2,0) -> DBC15A0 | E13: =VLOOKUP($C13,成品本月库存!$B:$J,5,0) -> PCS | H13: =VLOOKUP($C13,成品本月库存!$B:$J,9,0) -> 2352
C14: XFT010 | D14: =VLOOKUP($C14,成品本月库存!$B:$J,2,0) -> MHSP-SP-AX | E14: =VLOOKUP($C14,成品本月库存!$B:$J,5,0) -> PCS | F14: 12703 | H14: =VLOOKUP($C14,成品本月库存!$B:$J,9,0) -> 12778
C15: XFT010 | D15: MHSP-SP-AX | F15: 75 | G15: 洗白不良
C16: XFT011 | D16: =VLOOKUP($C16,成品本月库存!$B:$J,2,0) -> BHSP-SP-AX | E16: =VLOOKUP($C16,成品本月库存!$B:$J,5,0) -> PCS | F16: 136 | H16: =VLOOKUP($C16,成品本月库存!$B:$J,9,0) -> 136
C17: XFT012 | D17: =VLOOKUP($C17,成品本月库存!$B:$J,2,0) -> V3-BHSP-AX | E17: =VLOOKUP($C17,成品本月库存!$B:$J,5,0) -> PCS | F17: 1060 | H17: =VLOOKUP($C17,成品本月库存!$B:$J,9,0) -> 1060
C18: XFT015 | D18: =VLOOKUP($C18,成品本月库存!$B:$J,2,0) -> 盖板 | E18: =VLOOKUP($C18,成品本月库存!$B:$J,5,0) -> PCS | F18: 144 | H18: =VLOOKUP($C18,成品本月库存!$B:$J,9,0) -> 144
C19: XFT016 | D19: =VLOOKUP($C19,成品本月库存!$B:$J,2,0) -> ATT1LA-BHSP | E19: =VLOOKUP($C19,成品本月库存!$B:$J,5,0) -> PCS | F19: 1453 | H19: =VLOOKUP($C19,成品本月库存!$B:$J,9,0) -> 1453
C20: XFT017 | D20: =VLOOKUP($C20,成品本月库存!$B:$J,2,0) -> ATT1LA-PHSK | E20: =VLOOKUP($C20,成品本月库存!$B:$J,5,0) -> PCS | F20: =3634 -> 3634 | H20: =VLOOKUP($C20,成品本月库存!$B:$J,9,0) -> 3634
C21: XFT018-1 | D21: =VLOOKUP($C21,成品本月库存!$B:$J,2,0) -> ATT1LA-MHSP(8个牙） | E21: =VLOOKUP($C21,成品本月库存!$B:$J,5,0) -> PCS | F21: 1630 | H21: =VLOOKUP($C21,成品本月库存!$B:$J,9,0) -> 1630
C22: XFT019 | D22: =VLOOKUP($C22,成品本月库存!$B:$J,2,0) -> ATT1LA-THSP | E22: =VLOOKUP($C22,成品本月库存!$B:$J,5,0) -> PCS | F22: 403 | H22: =VLOOKUP($C22,成品本月库存!$B:$J,9,0) -> 639
C23: XFT019 | D23: ATT1LA-THSP | F23: 236 | G23: 电镀不良
C24: XFT029 | D24: =VLOOKUP($C24,成品本月库存!$B:$J,2,0) -> ZS-THSP | E24: =VLOOKUP($C24,成品本月库存!$B:$J,5,0) -> PCS | F24: 167 | H24: =VLOOKUP($C24,成品本月库存!$B:$J,9,0) -> 167
C25: XFT031 | D25: =VLOOKUP($C25,成品本月库存!$B:$J,2,0) -> ZS-MHSP | E25: =VLOOKUP($C25,成品本月库存!$B:$J,5,0) -> PCS | F25: 237 | H25: =VLOOKUP($C25,成品本月库存!$B:$J,9,0) -> 237
C26: XFT030 | D26: =VLOOKUP($C26,成品本月库存!$B:$J,2,0) -> ZS-BHSP | E26: =VLOOKUP($C26,成品本月库存!$B:$J,5,0) -> PCS | F26: 530 | H26: =VLOOKUP($C26,成品本月库存!$B:$J,9,0) -> 530
C27: XFT032 | D27: =VLOOKUP($C27,成品本月库存!$B:$J,2,0) -> DUD3500D1 | E27: =VLOOKUP($C27,成品本月库存!$B:$J,5,0) -> PCS | F27: =89+63 -> 152 | H27: =VLOOKUP($C27,成品本月库存!$B:$J,9,0) -> 149
C28: XFT033 | D28: =VLOOKUP($C28,成品本月库存!$B:$J,2,0) -> VSD9007S2 | E28: =VLOOKUP($C28,成品本月库存!$B:$J,5,0) -> PCS | F28: =14+1662 -> 1676 | H28: =VLOOKUP($C28,成品本月库存!$B:$J,9,0) -> 1676
C29: XFT034 | D29: =VLOOKUP($C29,成品本月库存!$B:$J,2,0) -> (002)Kreka MHSP Tool | E29: =VLOOKUP($C29,成品本月库存!$B:$J,5,0) -> PCS | F29: 194 | H29: =VLOOKUP($C29,成品本月库存!$B:$J,9,0) -> 194
C30: XFT037 | D30: =VLOOKUP($C30,成品本月库存!$B:$J,2,0) -> (003)Kreka THSP POR | E30: =VLOOKUP($C30,成品本月库存!$B:$J,5,0) -> PCS | F30: 242 | H30: =VLOOKUP($C30,成品本月库存!$B:$J,9,0) -> 242
C31: XFT040 | D31: =VLOOKUP($C31,成品本月库存!$B:$J,2,0) -> Barca-BHSP（4牙） | E31: =VLOOKUP($C31,成品本月库存!$B:$J,5,0) -> PCS | F31: 1652 | H31: =VLOOKUP($C31,成品本月库存!$B:$J,9,0) -> 1836
C32: XFT040 | D32: Barca-BHSP（4牙） | F32: 184 | G32: 烤漆不良
C33: XFT041 | D33: =VLOOKUP($C33,成品本月库存!$B:$J,2,0) -> Barca-MHSP （1牙） | E33: =VLOOKUP($C33,成品本月库存!$B:$J,5,0) -> PCS | F33: 2624 | H33: =VLOOKUP($C33,成品本月库存!$B:$J,9,0) -> 3102
C34: XFT041 | D34: Barca-MHSP （1牙） | F34: 478 | G34: 皮膜不良
C35: XFT044 | D35: =VLOOKUP($C35,成品本月库存!$B:$J,2,0) -> FVRB7813220（新电产） | E35: =VLOOKUP($C35,成品本月库存!$B:$J,5,0) -> PCS | F35: 362 | H35: =VLOOKUP($C35,成品本月库存!$B:$J,9,0) -> 362
C36: XFT046 | D36: =VLOOKUP($C36,成品本月库存!$B:$J,2,0) -> 0243B00100（金属外壳） | E36: =VLOOKUP($C36,成品本月库存!$B:$J,5,0) -> PCS | F36: =113 -> 113 | H36: =VLOOKUP($C36,成品本月库存!$B:$J,9,0) -> 113
C37: XFT047 | D37: =VLOOKUP($C37,成品本月库存!$B:$J,2,0) -> ME-003( THSP) | E37: =VLOOKUP($C37,成品本月库存!$B:$J,5,0) -> PCS | F37: 4312 | H37: =VLOOKUP($C37,成品本月库存!$B:$J,9,0) -> 4312
C38: XFT048 | D38: =VLOOKUP($C38,成品本月库存!$B:$J,2,0) -> ME-017(BHSP) | E38: =VLOOKUP($C38,成品本月库存!$B:$J,5,0) -> PCS | F38: 1768 | H38: =VLOOKUP($C38,成品本月库存!$B:$J,9,0) -> 1768
C39: XFT049 | D39: =VLOOKUP($C39,成品本月库存!$B:$J,2,0) -> ME-019(BTB SHELD) | E39: =VLOOKUP($C39,成品本月库存!$B:$J,5,0) -> PCS | F39: 1394 | H39: =VLOOKUP($C39,成品本月库存!$B:$J,9,0) -> 1394
C40: XFT051 | D40: =VLOOKUP($C40,成品本月库存!$B:$J,2,0) -> DBF7505L1 散熱片 | E40: =VLOOKUP($C40,成品本月库存!$B:$J,5,0) -> PCS | F40: 376 | H40: =VLOOKUP($C40,成品本月库存!$B:$J,9,0) -> 376
...

Sheet 成品入库明细
A1: 厂商 | B1: 日 期 | C1: 单据编号 | D1: 料号 | E1: 机种名称 | F1: 单位 | G1: 数量 | H1: 本月库存 | I1: 备注
A2: 锦宇树 | B2: 46209 | C2: 0006302 | D2: RB012-1 | E2: =VLOOKUP($D2,成品本月库存!$B:$J,2,0) -> 扳手810端盖--黑色 | F2: =VLOOKUP($D2,成品本月库存!$B:$J,5,0) -> PCS | G2: 2985 | H2: =VLOOKUP($D2,成品本月库存!$B:$J,9,0) -> 842
A3: 锦宇树 | B3: 46209 | C3: 0006302 | D3: RB026 | E3: =VLOOKUP($D3,成品本月库存!$B:$J,2,0) -> 扳手810STK2头壳 | F3: =VLOOKUP($D3,成品本月库存!$B:$J,5,0) -> PCS | G3: 1173 | H3: =VLOOKUP($D3,成品本月库存!$B:$J,9,0) -> -7
A4: 报废 | B4: 46207 | C4: 0002114 | D4: LX0010 | E4: =VLOOKUP($D4,成品本月库存!$B:$J,2,0) -> T93-20 | F4: =VLOOKUP($D4,成品本月库存!$B:$J,5,0) -> PCS | G4: -256 | H4: =VLOOKUP($D4,成品本月库存!$B:$J,9,0) -> 3846
A5: 报废 | B5: 46207 | C5: 0002114 | D5: RB043 | E5: =VLOOKUP($D5,成品本月库存!$B:$J,2,0) -> 起子机2108-L头壳含轴套 （世达款） | F5: =VLOOKUP($D5,成品本月库存!$B:$J,5,0) -> PCS | G5: -4 | H5: =VLOOKUP($D5,成品本月库存!$B:$J,9,0) -> 107
A6: 报废 | B6: 46207 | C6: 0002114 | D6: LX0023 | E6: =VLOOKUP($D6,成品本月库存!$B:$J,2,0) -> JK111-03机壳（无牙） | F6: =VLOOKUP($D6,成品本月库存!$B:$J,5,0) -> PCS | G6: -1 | H6: =VLOOKUP($D6,成品本月库存!$B:$J,9,0) -> 7933
A7: 报废 | B7: 46207 | C7: 0002114 | D7: LX0010 | E7: =VLOOKUP($D7,成品本月库存!$B:$J,2,0) -> T93-20 | F7: =VLOOKUP($D7,成品本月库存!$B:$J,5,0) -> PCS | G7: -155 | H7: =VLOOKUP($D7,成品本月库存!$B:$J,9,0) -> 3846
A8: 压铸 | B8: 46210 | C8: 0001252 | D8: ABL006 | E8: =VLOOKUP($D8,成品本月库存!$B:$J,2,0) -> 双嘴钳 | F8: =VLOOKUP($D8,成品本月库存!$B:$J,5,0) -> PCS | G8: 5088 | H8: =VLOOKUP($D8,成品本月库存!$B:$J,9,0) -> -7
A9: 锦宇树 | B9: 46210 | C9: 0006303 | D9: RB026-1 | E9: =VLOOKUP($D9,成品本月库存!$B:$J,2,0) -> 扳手810STK2头壳-黑色 | F9: =VLOOKUP($D9,成品本月库存!$B:$J,5,0) -> PCS | G9: 1000 | H9: =VLOOKUP($D9,成品本月库存!$B:$J,9,0) -> 2
A10: 锦宇树 | B10: 46210 | C10: 0006303 | D10: RB007 | E10: =VLOOKUP($D10,成品本月库存!$B:$J,2,0) -> 扳手818头壳（带花纹含轴套） | F10: =VLOOKUP($D10,成品本月库存!$B:$J,5,0) -> PCS | G10: 1200 | H10: =VLOOKUP($D10,成品本月库存!$B:$J,9,0) -> 4258
A11: 锦宇树 | B11: 46210 | C11: 0006303 | D11: RB002 | E11: =VLOOKUP($D11,成品本月库存!$B:$J,2,0) -> 扳手809头壳(含轴套) | F11: =VLOOKUP($D11,成品本月库存!$B:$J,5,0) -> PCS | G11: 3116 | H11: =VLOOKUP($D11,成品本月库存!$B:$J,9,0) -> 1675
A12: 锦宇树 | B12: 46210 | C12: 0006303 | D12: RB004 | E12: =VLOOKUP($D12,成品本月库存!$B:$J,2,0) -> 起子机2108-W头壳（230N头壳无轴套） | F12: =VLOOKUP($D12,成品本月库存!$B:$J,5,0) -> PCS | G12: 200 | H12: =VLOOKUP($D12,成品本月库存!$B:$J,9,0) -> 1670
A13: 锦拓 | B13: 46210 | C13: 0005835 | D13: HH0025 | E13: =VLOOKUP($D13,成品本月库存!$B:$J,2,0) -> HH8513旋钮 | F13: =VLOOKUP($D13,成品本月库存!$B:$J,5,0) -> PCS | G13: 5034 | H13: =VLOOKUP($D13,成品本月库存!$B:$J,9,0) -> 14190
... A21: 术尔 | B21: 46211 | C21: 0000018 | D21: HH0025 | E21: =VLOOKUP($D21,成品本月库存!$B:$J,2,0) -> HH8513旋钮 | F21: =VLOOKUP($D21,成品本月库存!$B:$J,5,0) -> PCS | G21: 4116 | H21: =VLOOKUP($D21,成品本月库存!$B:$J,9,0) -> 14190
E22: =VLOOKUP($D22,成品本月库存!$B:$J,2,0) -> #N/A | F22: =VLOOKUP($D22,成品本月库存!$B:$J,5,0) -> #N/A | H22: =VLOOKUP($D22,成品本月库存!$B:$J,9,0) -> #N/A
E23: =VLOOKUP($D23,成品本月库存!$B:$J,2,0) -> #N/A | F23: =VLOOKUP($D23,成品本月库存!$B:$J,5,0) -> #N/A | H23: =VLOOKUP($D23,成品本月库存!$B:$J,9,0) -> #N/A
E24: =VLOOKUP($D24,成品本月库存!$B:$J,2,0) -> #N/A | F24: =VLOOKUP($D24,成品本月库存!$B:$J,5,0) -> #N/A | H24: =VLOOKUP($D24,成品本月库存!$B:$J,9,0) -> #N/A
E25: =VLOOKUP($D25,成品本月库存!$B:$J,2,0) -> #N/A | F25: =VLOOKUP($D25,成品本月库存!$B:$J,5,0) -> #N/A | H25: =VLOOKUP($D25,成品本月库存!$B:$J,9,0) -> #N/A
E26: =VLOOKUP($D26,成品本月库存!$B:$J,2,0) -> #N/A | F26: =VLOOKUP($D26,成品本月库存!$B:$J,5,0) -> #N/A | H26: =VLOOKUP($D26,成品本月库存!$B:$J,9,0) -> #N/A
E27: =VLOOKUP($D27,成品本月库存!$B:$J,2,0) -> #N/A | F27: =VLOOKUP($D27,成品本月库存!$B:$J,5,0) -> #N/A | H27: =VLOOKUP($D27,成品本月库存!$B:$J,9,0) -> #N/A
E28: =VLOOKUP($D28,成品本月库存!$B:$J,2,0) -> #N/A | F28: =VLOOKUP($D28,成品本月库存!$B:$J,5,0) -> #N/A | H28: =VLOOKUP($D28,成品本月库存!$B:$J,9,0) -> #N/A
E29: =VLOOKUP($D29,成品本月库存!$B:$J,2,0) -> #N/A | F29: =VLOOKUP($D29,成品本月库存!$B:$J,5,0) -> #N/A | H29: =VLOOKUP($D29,成品本月库存!$B:$J,9,0) -> #N/A
E30: =VLOOKUP($D30,成品本月库存!$B:$J,2,0) -> #N/A | F30: =VLOOKUP($D30,成品本月库存!$B:$J,5,0) -> #N/A | H30: =VLOOKUP($D30,成品本月库存!$B:$J,9,0) -> #N/A
E31: =VLOOKUP($D31,成品本月库存!$B:$J,2,0) -> #N/A | F31: =VLOOKUP($D31,成品本月库存!$B:$J,5,0) -> #N/A | H31: =VLOOKUP($D31,成品本月库存!$B:$J,9,0) -> #N/A
E32: =VLOOKUP($D32,成品本月库存!$B:$J,2,0) -> #N/A | F32: =VLOOKUP($D32,成品本月库存!$B:$J,5,0) -> #N/A | H32: =VLOOKUP($D32,成品本月库存!$B:$J,9,0) -> #N/A
E33: =VLOOKUP($D33,成品本月库存!$B:$J,2,0) -> #N/A | F33: =VLOOKUP($D33,成品本月库存!$B:$J,5,0) -> #N/A | H33: =VLOOKUP($D33,成品本月库存!$B:$J,9,0) -> #N/A
... E501: =VLOOKUP($D501,成品本月库存!$B:$J,2,0) -> #N/A | F501: =VLOOKUP($D501,成品本月库存!$B:$J,5,0) -> #N/A | H501: =VLOOKUP($D501,成品本月库存!$B:$J,9,0) -> #N/A
H502: =VLOOKUP($D502,成品本月库存!$B:$J,9,0) -> #N/A

Sheet 成品出库明细
A1: 客户 | B1: 日 期 | C1: 单据编号 | D1: 料号 | E1: 机种名称 | F1: 单位 | G1: 数量 | H1: 本月库存
A2: 红黑 | B2: 46209 | D2: HH0025 | E2: =VLOOKUP($D2,成品本月库存!$B:$J,2,0) -> HH8513旋钮 | F2: =VLOOKUP($D2,成品本月库存!$B:$J,5,0) -> PCS | G2: -4917 | H2: =VLOOKUP($D2,成品本月库存!$B:$J,9,0) -> 14190 | I2: 退货
A3: 力硕 | B3: 46209 | D3: XFT032 | E3: =VLOOKUP($D3,成品本月库存!$B:$J,2,0) -> DUD3500D1 | F3: =VLOOKUP($D3,成品本月库存!$B:$J,5,0) -> PCS | G3: 3 | H3: =VLOOKUP($D3,成品本月库存!$B:$J,9,0) -> 149 | I3: 补不良
A4: 凯泰 | B4: 46209 | D4: KT005 | E4: =VLOOKUP($D4,成品本月库存!$B:$J,2,0) -> 双目支架 | F4: =VLOOKUP($D4,成品本月库存!$B:$J,5,0) -> PCS | G4: 3120 | H4: =VLOOKUP($D4,成品本月库存!$B:$J,9,0) -> 16091
A5: 朗信 | B5: 46209 | D5: LX0003 | E5: =VLOOKUP($D5,成品本月库存!$B:$J,2,0) -> T93-13 | F5: =VLOOKUP($D5,成品本月库存!$B:$J,5,0) -> PCS | G5: 1350 | H5: =VLOOKUP($D5,成品本月库存!$B:$J,9,0) -> 1278
A6: 朗信 | B6: 46209 | D6: LX0010 | E6: =VLOOKUP($D6,成品本月库存!$B:$J,2,0) -> T93-20 | F6: =VLOOKUP($D6,成品本月库存!$B:$J,5,0) -> PCS | G6: 7020 | H6: =VLOOKUP($D6,成品本月库存!$B:$J,9,0) -> 3846
A7: 朗信 | B7: 46209 | D7: LX0019-1 | E7: =VLOOKUP($D7,成品本月库存!$B:$J,2,0) -> T93-29镭雕 | F7: =VLOOKUP($D7,成品本月库存!$B:$J,5,0) -> PCS | G7: 1350 | H7: =VLOOKUP($D7,成品本月库存!$B:$J,9,0) -> 877
A8: 朗信 | B8: 46209 | D8: LX0023 | E8: =VLOOKUP($D8,成品本月库存!$B:$J,2,0) -> JK111-03机壳（无牙） | F8: =VLOOKUP($D8,成品本月库存!$B:$J,5,0) -> PCS | G8: 1350 | H8: =VLOOKUP($D8,成品本月库存!$B:$J,9,0) -> 7933
A9: 金脉 | B9: 46210 | D9: JM0004 | E9: =VLOOKUP($D9,成品本月库存!$B:$J,2,0) -> G2124DM11B01 | F9: =VLOOKUP($D9,成品本月库存!$B:$J,5,0) -> PCS | G9: 1200 | H9: =VLOOKUP($D9,成品本月库存!$B:$J,9,0) -> 6376
A10: 报废 | B10: 46209 | C10: 0001456 | D10: LX0010 | E10: =VLOOKUP($D10,成品本月库存!$B:$J,2,0) -> T93-20 | F10: =VLOOKUP($D10,成品本月库存!$B:$J,5,0) -> PCS | G10: 149 | H10: =VLOOKUP($D10,成品本月库存!$B:$J,9,0) -> 3846
A11: 报废 | B11: 46209 | C11: 0001456 | D11: RB026 | E11: =VLOOKUP($D11,成品本月库存!$B:$J,2,0) -> 扳手810STK2头壳 | F11: =VLOOKUP($D11,成品本月库存!$B:$J,5,0) -> PCS | G11: 2 | H11: =VLOOKUP($D11,成品本月库存!$B:$J,9,0) -> -7
A12: 报废 | B12: 46209 | C12: 0001456 | D12: RB007 | E12: =VLOOKUP($D12,成品本月库存!$B:$J,2,0) -> 扳手818头壳（带花纹含轴套） | F12: =VLOOKUP($D12,成品本月库存!$B:$J,5,0) -> PCS | G12: 4 | H12: =VLOOKUP($D12,成品本月库存!$B:$J,9,0) -> 4258
A13: 报废 | B13: 46209 | C13: 0001456 | D13: RB002 | E13: =VLOOKUP($D13,成品本月库存!$B:$J,2,0) -> 扳手809头壳(含轴套) | F13: =VLOOKUP($D13,成品本月库存!$B:$J,5,0) -> PCS | G13: 178 | H13: =VLOOKUP($D13,成品本月库存!$B:$J,9,0) -> 1675
A14: 报废 | B14: 46209 | C14: 0001456 | D14: RB038 | E14: =VLOOKUP($D14,成品本月库存!$B:$J,2,0) -> 黄油枪HY01A齿轮箱 | F14: =VLOOKUP($D14,成品本月库存!$B:$J,5,0) -> PCS | G14: 5 | H14: =VLOOKUP($D14,成品本月库存!$B:$J,9,0) -> 4
A15: 报废 | B15: 46209 | C15: 0001456 | D15: RB026 | E15: =VLOOKUP($D15,成品本月库存!$B:$J,2,0) -> 扳手810STK2头壳 | F15: =VLOOKUP($D15,成品本月库存!$B:$J,5,0) -> PCS | G15: 14 | H15: =VLOOKUP($D15,成品本月库存!$B:$J,9,0) -> -7
A16: 报废 | B16: 46209 | C16: 0001456 | D16: RB012-1 | E16: =VLOOKUP($D16,成品本月库存!$B:$J,2,0) -> 扳手810端盖--黑色 | F16: =VLOOKUP($D16,成品本月库存!$B:$J,5,0) -> PCS | G16: 13 | H16: =VLOOKUP($D16,成品本月库存!$B:$J,9,0) -> 842
A17: 报废 | B17: 46209 | C17: 0001456 | D17: RB012-1 | E17: =VLOOKUP($D17,成品本月库存!$B:$J,2,0) -> 扳手810端盖--黑色 | F17: =VLOOKUP($D17,成品本月库存!$B:$J,5,0) -> PCS | G17: 97 | H17: =VLOOKUP($D17,成品本月库存!$B:$J,9,0) -> 842
A18: 报废 | B18: 46210 | C18: 0001457 | D18: LX0020-1 | E18: =VLOOKUP($D18,成品本月库存!$B:$J,2,0) -> T93-33镭雕（4孔） | F18: =VLOOKUP($D18,成品本月库存!$B:$J,5,0) -> PCS | G18: 19 | H18: =VLOOKUP($D18,成品本月库存!$B:$J,9,0) -> 887
A19: 报废 | B19: 46210 | C19: 0001457 | D19: LX0020-1 | E19: =VLOOKUP($D19,成品本月库存!$B:$J,2,0) -> T93-33镭雕（4孔） | F19: =VLOOKUP($D19,成品本月库存!$B:$J,5,0) -> PCS | G19: 6 | H19: =VLOOKUP($D19,成品本月库存!$B:$J,9,0) -> 887
A20: 报废 | B20: 46210 | C20: 0001457 | D20: LX0019-1 | E20: =VLOOKUP($D20,成品本月库存!$B:$J,2,0) -> T93-29镭雕 | F20: =VLOOKUP($D20,成品本月库存!$B:$J,5,0) -> PCS | G20: 24 | H20: =VLOOKUP($D20,成品本月库存!$B:$J,9,0) -> 877
A21: 报废 | B21: 46210 | C21: 0001457 | D21: LX0019-1 | E21: =VLOOKUP($D21,成品本月库存!$B:$J,2,0) -> T93-29镭雕 | F21: =VLOOKUP($D21,成品本月库存!$B:$J,5,0) -> PCS | G21: 11 | H21: =VLOOKUP($D21,成品本月库存!$B:$J,9,0) -> 877
... A25: 报废 | B25: 46210 | C25: 0001457 | D25: JM0004 | E25: =VLOOKUP($D25,成品本月库存!$B:$J,2,0) -> G2124DM11B01 | F25: =VLOOKUP($D25,成品本月库存!$B:$J,5,0) -> PCS | G25: 8 | H25: =VLOOKUP($D25,成品本月库存!$B:$J,9,0) -> 6376
A26: 晨兴德 | B26: 46211 | C26: 0000105 | D26: CXD001 | E26: =VLOOKUP($D26,成品本月库存!$B:$J,2,0) -> M3 Sus TS brt LS 左摆臂 | F26: =VLOOKUP($D26,成品本月库存!$B:$J,5,0) -> PCS | G26: -761 | H26: =VLOOKUP($D26,成品本月库存!$B:$J,9,0) -> 761 | I26: 退货
A27: 晨兴德 | B27: 46211 | C27: 0000105 | D27: CXD002 | E27: =VLOOKUP($D27,成品本月库存!$B:$J,2,0) -> M3 Sus TS brt RS 右摆臂 | F27: =VLOOKUP($D27,成品本月库存!$B:$J,5,0) -> PCS | G27: -360 | H27: =VLOOKUP($D27,成品本月库存!$B:$J,9,0) -> 360 | I27: 退货
A28: 红黑 | B28: 46211 | D28: HH0027 | E28: =VLOOKUP($D28,成品本月库存!$B:$J,2,0) -> 铝压盖/8526 | F28: =VLOOKUP($D28,成品本月库存!$B:$J,5,0) -> PCS | G28: 10 | H28: =VLOOKUP($D28,成品本月库存!$B:$J,9,0) -> 1824 | I28: 换货
A29: 红黑 | B29: 46211 | D29: HH0028 | E29: =VLOOKUP($D29,成品本月库存!$B:$J,2,0) -> 8527旋钮 | F29: =VLOOKUP($D29,成品本月库存!$B:$J,5,0) -> PCS | G29: 10 | H29: =VLOOKUP($D29,成品本月库存!$B:$J,9,0) -> 104
A30: 红黑 | B30: 46211 | D30: HH0028 | E30: =VLOOKUP($D30,成品本月库存!$B:$J,2,0) -> 8527旋钮 | F30: =VLOOKUP($D30,成品本月库存!$B:$J,5,0) -> PCS | G30: 10 | H30: =VLOOKUP($D30,成品本月库存!$B:$J,9,0) -> 104
A31: 红黑 | B31: 46211 | D31: HH0028 | E31: =VLOOKUP($D31,成品本月库存!$B:$J,2,0) -> 8527旋钮 | F31: =VLOOKUP($D31,成品本月库存!$B:$J,5,0) -> PCS | G31: 10 | H31: =VLOOKUP($D31,成品本月库存!$B:$J,9,0) -> 104
A32: 爱毕黎 | B32: 46211 | D32: ABL006 | E32: =VLOOKUP($D32,成品本月库存!$B:$J,2,0) -> 双嘴钳 | F32: =VLOOKUP($D32,成品本月库存!$B:$J,5,0) -> PCS | G32: 5095 | H32: =VLOOKUP($D32,成品本月库存!$B:$J,9,0) -> -7
A33: 锐霸 | B33: 46211 | D33: RB002 | E33: =VLOOKUP($D33,成品本月库存!$B:$J,2,0) -> 扳手809头壳(含轴套) | F33: =VLOOKUP($D33,成品本月库存!$B:$J,5,0) -> PCS | G33: 3363 | H33: =VLOOKUP($D33,成品本月库存!$B:$J,9,0) -> 1675
A34: 锐霸 | B34: 46211 | D34: RB026 | E34: =VLOOKUP($D34,成品本月库存!$B:$J,2,0) -> 扳手810STK2头壳 | F34: =VLOOKUP($D34,成品本月库存!$B:$J,5,0) -> PCS | G34: 3369 | H34: =VLOOKUP($D34,成品本月库存!$B:$J,9,0) -> -7
A35: 锐霸 | B35: 46211 | D35: RB028 | E35: =VLOOKUP($D35,成品本月库存!$B:$J,2,0) -> 扳手809S 头壳 世达款 | F35: =VLOOKUP($D35,成品本月库存!$B:$J,5,0) -> PCS | G35: 707 | H35: =VLOOKUP($D35,成品本月库存!$B:$J,9,0) -> 0
A36: 锐霸 | B36: 46211 | D36: RB038 | E36: =VLOOKUP($D36,成品本月库存!$B:$J,2,0) -> 黄油枪HY01A齿轮箱 | F36: =VLOOKUP($D36,成品本月库存!$B:$J,5,0) -> PCS | G36: 336 | H36: =VLOOKUP($D36,成品本月库存!$B:$J,9,0) -> 4
A37: 锐霸 | B37: 46211 | D37: RB004 | E37: =VLOOKUP($D37,成品本月库存!$B:$J,2,0) -> 起子机2108-W头壳（230N头壳无轴套） | F37: =VLOOKUP($D37,成品本月库存!$B:$J,5,0) -> PCS | G37: 200 | H37: =VLOOKUP($D37,成品本月库存!$B:$J,9,0) -> 1670
A38: 锐霸 | B38: 46212 | D38: RB025 | E38: =VLOOKUP($D38,成品本月库存!$B:$J,2,0) -> 扳手806S头壳 SD | F38: =VLOOKUP($D38,成品本月库存!$B:$J,5,0) -> PCS | G38: 2679 | H38: =VLOOKUP($D38,成品本月库存!$B:$J,9,0) -> -247
A39: 锐霸 | B39: 46212 | D39: RB026-1 | E39: =VLOOKUP($D39,成品本月库存!$B:$J,2,0) -> 扳手810STK2头壳-黑色 | F39: =VLOOKUP($D39,成品本月库存!$B:$J,5,0) -> PCS | G39: 2051 | H39: =VLOOKUP($D39,成品本月库存!$B:$J,9,0) -> 2
A40: 锐霸 | B40: 46212 | D40: RB012-1 | E40: =VLOOKUP($D40,成品本月库存!$B:$J,2,0) -> 扳手810端盖--黑色 | F40: =VLOOKUP($D40,成品本月库存!$B:$J,5,0) -> PCS | G40: 2033 | H40: =VLOOKUP($D40,成品本月库存!$B:$J,9,0) -> 842
... A47: 朗信 | B47: 46212 | D47: LX0019-1 | E47: =VLOOKUP($D47,成品本月库存!$B:$J,2,0) -> T93-29镭雕 | F47: =VLOOKUP($D47,成品本月库存!$B:$J,5,0) -> PCS | G47: 1350 | H47: =VLOOKUP($D47,成品本月库存!$B:$J,9,0) -> 877
A48: 凯泰 | B48: 46212 | D48: KT005 | E48: =VLOOKUP($D48,成品本月库存!$B:$J,2,0) -> 双目支架 | F48: =VLOOKUP($D48,成品本月库存!$B:$J,5,0) -> PCS | G48: -3085 | H48: =VLOOKUP($D48,成品本月库存!$B:$J,9,0) -> 16091 | I48: 退货
E49: =VLOOKUP($D49,成品本月库存!$B:$J,2,0) -> #N/A | F49: =VLOOKUP($D49,成品本月库存!$B:$J,5,0) -> #N/A | H49: =VLOOKUP($D49,成品本月库存!$B:$J,9,0) -> #N/A
...

Sheet 成品本月库存
A1: 1 | B1: 料号 | C1: 料号 | D1: 客户 | E1: 成品 | F1: 单位 | G1: 月初库存 | H1: 本月入库 | I1: 本月出库 | J1: 本月结存 | K1: 备注最后工艺 | XFD1: =SUM(A1:XFC1) -> 1
A2: 2 | B2: ZM0001 | C2: H56上盖 | D2: 纵目 | E2: 成品 | F2: PCS | G2: =SUMIF(成品月初库存!$C$3:$C$362,$B2,成品月初库存!$F$3:$F$362) -> 0 | H2: =SUMIF(成品入库明细!$D$2:$D$500,$B2,成品入库明细!$G$2:$G$500) -> 0 | I2: =SUMIF(成品出库明细!$D$2:$D$1172,$B2,成品出库明细!$G$2:$G$1172) -> 0 | J2: =G2+H2-I2 -> 0 | K2: 皮膜
A3: 3 | B3: ZM0002 | C3: H56下盖 | D3: 纵目 | E3: 成品 | F3: PCS | G3: =SUMIF(成品月初库存!$C$3:$C$362,$B3,成品月初库存!$F$3:$F$362) -> 0 | H3: =SUMIF(成品入库明细!$D$2:$D$500,$B3,成品入库明细!$G$2:$G$500) -> 0 | I3: =SUMIF(成品出库明细!$D$2:$D$1172,$B3,成品出库明细!$G$2:$G$1172) -> 0 | J3: =G3+H3-I3 -> 0 | K3: 皮膜
A4: 4 | B4: ZM0003 | C4: 金康X1上盖 | D4: 纵目 | E4: 成品 | F4: PCS | G4: =SUMIF(成品月初库存!$C$3:$C$362,$B4,成品月初库存!$F$3:$F$362) -> 0 | H4: =SUMIF(成品入库明细!$D$2:$D$500,$B4,成品入库明细!$G$2:$G$500) -> 0 | I4: =SUMIF(成品出库明细!$D$2:$D$1172,$B4,成品出库明细!$G$2:$G$1172) -> 0 | J4: =G4+H4-I4 -> 0 | K4: 振研
A5: 5 | B5: ZM0004 | C5: 金康X1下盖 | D5: 纵目 | E5: 成品 | F5: PCS | G5: =SUMIF(成品月初库存!$C$3:$C$362,$B5,成品月初库存!$F$3:$F$362) -> 0 | H5: =SUMIF(成品入库明细!$D$2:$D$500,$B5,成品入库明细!$G$2:$G$500) -> 0 | I5: =SUMIF(成品出库明细!$D$2:$D$1172,$B5,成品出库明细!$G$2:$G$1172) -> 0 | J5: =G5+H5-I5 -> 0 | K5: 振研
A6: 6 | B6: ZM0003-F1 | C6: 金康F1上盖 | D6: 纵目 | E6: 成品 | F6: PCS | G6: =SUMIF(成品月初库存!$C$3:$C$362,$B6,成品月初库存!$F$3:$F$362) -> 0 | H6: =SUMIF(成品入库明细!$D$2:$D$500,$B6,成品入库明细!$G$2:$G$500) -> 0 | I6: =SUMIF(成品出库明细!$D$2:$D$1172,$B6,成品出库明细!$G$2:$G$1172) -> 0 | J6: =G6+H6-I6 -> 0 | K6: 振研（含CNC)
A7: 7 | B7: ZM0005 | C7: C385上盖 | D7: 纵目 | E7: 成品 | F7: PCS | G7: =SUMIF(成品月初库存!$C$3:$C$362,$B7,成品月初库存!$F$3:$F$362) -> 0 | H7: =SUMIF(成品入库明细!$D$2:$D$500,$B7,成品入库明细!$G$2:$G$500) -> 0 | I7: =SUMIF(成品出库明细!$D$2:$D$1172,$B7,成品出库明细!$G$2:$G$1172) -> 0 | J7: =G7+H7-I7 -> 0 | K7: 皮膜（钝化）
A8: 8 | B8: ZM0005-1 | C8: C385上盖 | D8: 纵目 | E8: 成品 | F8: PCS | G8: =SUMIF(成品月初库存!$C$3:$C$362,$B8,成品月初库存!$F$3:$F$362) -> 0 | H8: =SUMIF(成品入库明细!$D$2:$D$500,$B8,成品入库明细!$G$2:$G$500) -> 0 | I8: =SUMIF(成品出库明细!$D$2:$D$1172,$B8,成品出库明细!$G$2:$G$1172) -> 0 | J8: =G8+H8-I8 -> 0 | K8: 成品（临时）
A9: 9 | B9: ZM0006 | C9: C385下盖 | D9: 纵目 | E9: 成品 | F9: PCS | G9: =SUMIF(成品月初库存!$C$3:$C$362,$B9,成品月初库存!$F$3:$F$362) -> 0 | H9: =SUMIF(成品入库明细!$D$2:$D$500,$B9,成品入库明细!$G$2:$G$500) -> 0 | I9: =SUMIF(成品出库明细!$D$2:$D$1172,$B9,成品出库明细!$G$2:$G$1172) -> 0 | J9: =G9+H9-I9 -> 0 | K9: 皮膜（钝化）
A10: 10 | B10: ZM0006-1 | C10: C385下盖 | D10: 纵目 | E10: 成品 | F10: PCS | G10: =SUMIF(成品月初库存!$C$3:$C$362,$B10,成品月初库存!$F$3:$F$362) -> 0 | H10: =SUMIF(成品入库明细!$D$2:$D$500,$B10,成品入库明细!$G$2:$G$500) -> 0 | I10: =SUMIF(成品出库明细!$D$2:$D$1172,$B10,成品出库明细!$G$2:$G$1172) -> 0 | J10: =G10+H10-I10 -> 0 | K10: 成品（临时）
A11: 11 | B11: ZM0007 | C11: C001_APA主机上盖 | D11: 纵目 | E11: 成品 | F11: PCS | G11: =SUMIF(成品月初库存!$C$3:$C$362,$B11,成品月初库存!$F$3:$F$362) -> 0 | H11: =SUMIF(成品入库明细!$D$2:$D$500,$B11,成品入库明细!$G$2:$G$500) -> 0 | I11: =SUMIF(成品出库明细!$D$2:$D$1172,$B11,成品出库明细!$G$2:$G$1172) -> 0 | J11: =G11+H11-I11 -> 0 | K11: 振研
A12: 12 | B12: ZM0008 | C12: C001_APA主机下盖 | D12: 纵目 | E12: 成品 | F12: PCS | G12: =SUMIF(成品月初库存!$C$3:$C$362,$B12,成品月初库存!$F$3:$F$362) -> 0 | H12: =SUMIF(成品入库明细!$D$2:$D$500,$B12,成品入库明细!$G$2:$G$500) -> 0 | I12: =SUMIF(成品出库明细!$D$2:$D$1172,$B12,成品出库明细!$G$2:$G$1172) -> 0 | J12: =G12+H12-I12 -> 0 | K12: 振研
A13: 13 | B13: ZM001 | C13: P-3 | D13: 卓民 | E13: 成品 | F13: PCS | G13: =SUMIF(成品月初库存!$C$3:$C$362,$B13,成品月初库存!$F$3:$F$362) -> 0 | H13: =SUMIF(成品入库明细!$D$2:$D$500,$B13,成品入库明细!$G$2:$G$500) -> 0 | I13: =SUMIF(成品出库明细!$D$2:$D$1172,$B13,成品出库明细!$G$2:$G$1172) -> 0 | J13: =G13+H13-I13 -> 0 | K13: 烤漆
... A57: 57 | B57: XFT002 | C57: 0008 | D57: 鑫福泰 | E57: 成品 | F57: PCS | G57: =SUMIF(成品月初库存!$C$3:$C$362,$B57,成品月初库存!$F$3:$F$362) -> 6097 | H57: =SUMIF(成品入库明细!$D$2:$D$500,$B57,成品入库明细!$G$2:$G$500) -> 0 | I57: =SUMIF(成品出库明细!$D$2:$D$1172,$B57,成品出库明细!$G$2:$G$1172) -> 0 | J57: =G57+H57-I57 -> 6097 | K57: 皮膜
A58: 58 | B58: XFT003 | C58: 0009中框 | D58: 鑫福泰 | E58: 成品 | F58: PCS | G58: =SUMIF(成品月初库存!$C$3:$C$362,$B58,成品月初库存!$F$3:$F$362) -> 22323 | H58: =SUMIF(成品入库明细!$D$2:$D$500,$B58,成品入库明细!$G$2:$G$500) -> 0 | I58: =SUMIF(成品出库明细!$D$2:$D$1172,$B58,成品出库明细!$G$2:$G$1172) -> 0 | J58: =G58+H58-I58 -> 22323 | K58: 烤漆 | L58: 71U00145
A59: 59 | B59: XFT004 | C59: DBC1481L1 | D59: 鑫福泰 | E59: 成品 | F59: PCS | G59: =SUMIF(成品月初库存!$C$3:$C$362,$B59,成品月初库存!$F$3:$F$362) -> 2424 | H59: =SUMIF(成品入库明细!$D$2:$D$500,$B59,成品入库明细!$G$2:$G$500) -> 0 | I59: =SUMIF(成品出库明细!$D$2:$D$1172,$B59,成品出库明细!$G$2:$G$1172) -> 0 | J59: =G59+H59-I59 -> 2424 | K59: 皮膜
A60: 60 | B60: XFT005 | C60: DBC1480L1 | D60: 鑫福泰 | E60: 成品 | F60: PCS | G60: =SUMIF(成品月初库存!$C$3:$C$362,$B60,成品月初库存!$F$3:$F$362) -> 270 | H60: =SUMIF(成品入库明细!$D$2:$D$500,$B60,成品入库明细!$G$2:$G$500) -> 0 | I60: =SUMIF(成品出库明细!$D$2:$D$1172,$B60,成品出库明细!$G$2:$G$1172) -> 0 | J60: =G60+H60-I60 -> 270 | K60: 皮膜
A61: 61 | B61: XFT006 | C61: UDU9011 | D61: 鑫福泰 | E61: 成品 | F61: PCS | G61: =SUMIF(成品月初库存!$C$3:$C$362,$B61,成品月初库存!$F$3:$F$362) -> 0 | H61: =SUMIF(成品入库明细!$D$2:$D$500,$B61,成品入库明细!$G$2:$G$500) -> 0 | I61: =SUMIF(成品出库明细!$D$2:$D$1172,$B61,成品出库明细!$G$2:$G$1172) -> 0 | J61: =G61+H61-I61 -> 0 | K61: 电镀
A62: 62 | B62: XFT007 | C62: DBC15A0 | D62: 鑫福泰 | E62: 成品 | F62: PCS | G62: =SUMIF(成品月初库存!$C$3:$C$362,$B62,成品月初库存!$F$3:$F$362) -> 2352 | H62: =SUMIF(成品入库明细!$D$2:$D$500,$B62,成品入库明细!$G$2:$G$500) -> 0 | I62: =SUMIF(成品出库明细!$D$2:$D$1172,$B62,成品出库明细!$G$2:$G$1172) -> 0 | J62: =G62+H62-I62 -> 2352 | K62: 皮膜
A63: 63 | B63: XFT008 | C63: 0007-001 | D63: 鑫福泰 | E63: 成品 | F63: PCS | G63: =SUMIF(成品月初库存!$C$3:$C$362,$B63,成品月初库存!$F$3:$F$362) -> 0 | H63: =SUMIF(成品入库明细!$D$2:$D$500,$B63,成品入库明细!$G$2:$G$500) -> 0 | I63: =SUMIF(成品出库明细!$D$2:$D$1172,$B63,成品出库明细!$G$2:$G$1172) -> 0 | J63: =G63+H63-I63 -> 0 | K63: 电镀
A64: 64 | B64: XFT009 | C64: 70U00162 | D64: 鑫福泰 | E64: 成品 | F64: PCS | G64: =SUMIF(成品月初库存!$C$3:$C$362,$B64,成品月初库存!$F$3:$F$362) -> 0 | H64: =SUMIF(成品入库明细!$D$2:$D$500,$B64,成品入库明细!$G$2:$G$500) -> 0 | I64: =SUMIF(成品出库明细!$D$2:$D$1172,$B64,成品出库明细!$G$2:$G$1172) -> 0 | J64: =G64+H64-I64 -> 0 | K64: 皮膜
A65: 65 | B65: XFT010 | C65: MHSP-SP-AX | D65: 鑫福泰 | E65: 成品 | F65: PCS | G65: =SUMIF(成品月初库存!$C$3:$C$362,$B65,成品月初库存!$F$3:$F$362) -> 12778 | H65: =SUMIF(成品入库明细!$D$2:$D$500,$B65,成品入库明细!$G$2:$G$500) -> 0 | I65: =SUMIF(成品出库明细!$D$2:$D$1172,$B65,成品出库明细!$G$2:$G$1172) -> 0 | J65: =G65+H65-I65 -> 12778 | K65: 皮膜
A66: 66 | B66: XFT011 | C66: BHSP-SP-AX | D66: 鑫福泰 | E66: 成品 | F66: PCS | G66: =SUMIF(成品月初库存!$C$3:$C$362,$B66,成品月初库存!$F$3:$F$362) -> 136 | H66: =SUMIF(成品入库明细!$D$2:$D$500,$B66,成品入库明细!$G$2:$G$500) -> 0 | I66: =SUMIF(成品出库明细!$D$2:$D$1172,$B66,成品出库明细!$G$2:$G$1172) -> 0 | J66: =G66+H66-I66 -> 136 | K66: 烤漆
A67: 67 | B67: XFT012 | C67: V3-BHSP-AX | D67: 鑫福泰 | E67: 成品 | F67: PCS | G67: =SUMIF(成品月初库存!$C$3:$C$362,$B67,成品月初库存!$F$3:$F$362) -> 1060 | H67: =SUMIF(成品入库明细!$D$2:$D$500,$B67,成品入库明细!$G$2:$G$500) -> 0 | I67: =SUMIF(成品出库明细!$D$2:$D$1172,$B67,成品出库明细!$G$2:$G$1172) -> 0 | J67: =G67+H67-I67 -> 1060 | K67: 烤漆
A68: 68 | B68: XFT013 | C68: 后盖 | D68: 鑫福泰 | E68: 成品 | F68: PCS | G68: =SUMIF(成品月初库存!$C$3:$C$362,$B68,成品月初库存!$F$3:$F$362) -> 0 | H68: =SUMIF(成品入库明细!$D$2:$D$500,$B68,成品入库明细!$G$2:$G$500) -> 0 | I68: =SUMIF(成品出库明细!$D$2:$D$1172,$B68,成品出库明细!$G$2:$G$1172) -> 0 | J68: =G68+H68-I68 -> 0 | K68: 丝印
A69: 69 | B69: XFT014 | C69: 前盖 | D69: 鑫福泰 | E69: 成品 | F69: PCS | G69: =SUMIF(成品月初库存!$C$3:$C$362,$B69,成品月初库存!$F$3:$F$362) -> 0 | H69: =SUMIF(成品入库明细!$D$2:$D$500,$B69,成品入库明细!$G$2:$G$500) -> 0 | I69: =SUMIF(成品出库明细!$D$2:$D$1172,$B69,成品出库明细!$G$2:$G$1172) -> 0 | J69: =G69+H69-I69 -> 0 | K69: 烤漆
A70: 70 | B70: XFT015 | C70: 盖板 | D70: 鑫福泰 | E70: 成品 | F70: PCS | G70: =SUMIF(成品月初库存!$C$3:$C$362,$B70,成品月初库存!$F$3:$F$362) -> 144 | H70: =SUMIF(成品入库明细!$D$2:$D$500,$B70,成品入库明细!$G$2:$G$500) -> 0 | I70: =SUMIF(成品出库明细!$D$2:$D$1172,$B70,成品出库明细!$G$2:$G$1172) -> 0 | J70: =G70+H70-I70 -> 144 | K70: 烤漆
... A73: 73 | B73: XFT018 | C73: ATT1LA-MHSP（4个牙） | D73: 鑫福泰 | E73: 成品 | F73: PCS | G73: =SUMIF(成品月初库存!$C$3:$C$362,$B73,成品月初库存!$F$3:$F$362) -> 0 | H73: =SUMIF(成品入库明细!$D$2:$D$500,$B73,成品入库明细!$G$2:$G$500) -> 0 | I73: =SUMIF(成品出库明细!$D$2:$D$1172,$B73,成品出库明细!$G$2:$G$1172) -> 0 | J73: =G73+H73-I73 -> 0 | K73: 拉白
B74: XFT018-1 | C74: ATT1LA-MHSP(8个牙） | D74: 鑫福泰 | E74: 成品 | F74: PCS | G74: =SUMIF(成品月初库存!$C$3:$C$362,$B74,成品月初库存!$F$3:$F$362) -> 1630 | H74: =SUMIF(成品入库明细!$D$2:$D$500,$B74,成品入库明细!$G$2:$G$500) -> 0 | I74: =SUMIF(成品出库明细!$D$2:$D$1172,$B74,成品出库明细!$G$2:$G$1172) -> 0 | J74: =G74+H74-I74 -> 1630 | K74: 拉白
A75: 74 | B75: XFT019 | C75: ATT1LA-THSP | D75: 鑫福泰 | E75: 成品 | F75: PCS | G75: =SUMIF(成品月初库存!$C$3:$C$362,$B75,成品月初库存!$F$3:$F$362) -> 639 | H75: =SUMIF(成品入库明细!$D$2:$D$500,$B75,成品入库明细!$G$2:$G$500) -> 0 | I75: =SUMIF(成品出库明细!$D$2:$D$1172,$B75,成品出库明细!$G$2:$G$1172) -> 0 | J75: =G75+H75-I75 -> 639 | K75: 电镀
A76: 75 | B76: XFT0017 | C76: 锌合金-1 | D76: 鑫福泰 | E76: 成品 | F76: PCS | G76: =SUMIF(成品月初库存!$C$3:$C$362,$B76,成品月初库存!$F$3:$F$362) -> 0 | H76: =SUMIF(成品入库明细!$D$2:$D$500,$B76,成品入库明细!$G$2:$G$500) -> 0 | I76: =SUMIF(成品出库明细!$D$2:$D$1172,$B76,成品出库明细!$G$2:$G$1172) -> 0 | J76: =G76+H76-I76 -> 0 | K76: 电泳
A77: 76 | B77: XFT0018 | C77: 锌合金-2 | D77: 鑫福泰 | E77: 成品 | F77: PCS | G77: =SUMIF(成品月初库存!$C$3:$C$362,$B77,成品月初库存!$F$3:$F$362) -> 0 | H77: =SUMIF(成品入库明细!$D$2:$D$500,$B77,成品入库明细!$G$2:$G$500) -> 0 | I77: =SUMIF(成品出库明细!$D$2:$D$1172,$B77,成品出库明细!$G$2:$G$1172) -> 0 | J77: =G77+H77-I77 -> 0 | K77: 电泳
A78: 77 | B78: XFT028 | C78: 9012上盖 | D78: 鑫福泰 | E78: 成品 | F78: PCS | G78: =SUMIF(成品月初库存!$C$3:$C$362,$B78,成品月初库存!$F$3:$F$362) -> 0 | H78: =SUMIF(成品入库明细!$D$2:$D$500,$B78,成品入库明细!$G$2:$G$500) -> 0 | I78: =SUMIF(成品出库明细!$D$2:$D$1172,$B78,成品出库明细!$G$2:$G$1172) -> 0 | J78: =G78+H78-I78 -> 0 | K78: 镭雕
A79: 78 | B79: XFT029 | C79: ZS-THSP | D79: 鑫福泰 | E79: 成品 | F79: PCS | G79: =SUMIF(成品月初库存!$C$3:$C$362,$B79,成品月初库存!$F$3:$F$362) -> 167 | H79: =SUMIF(成品入库明细!$D$2:$D$500,$B79,成品入库明细!$G$2:$G$500) -> 0 | I79: =SUMIF(成品出库明细!$D$2:$D$1172,$B79,成品出库明细!$G$2:$G$1172) -> 0 | J79: =G79+H79-I79 -> 167 | K79: 电镀
A80: 79 | B80: XFT031 | C80: ZS-MHSP | D80: 鑫福泰 | E80: 成品 | F80: PCS | G80: =SUMIF(成品月初库存!$C$3:$C$362,$B80,成品月初库存!$F$3:$F$362) -> 237 | H80: =SUMIF(成品入库明细!$D$2:$D$500,$B80,成品入库明细!$G$2:$G$500) -> 0 | I80: =SUMIF(成品出库明细!$D$2:$D$1172,$B80,成品出库明细!$G$2:$G$1172) -> 0 | J80: =G80+H80-I80 -> 237 | K80: 皮膜
A81: 80 | B81: XFT030 | C81: ZS-BHSP | D81: 鑫福泰 | E81: 成品 | F81: PCS | G81: =SUMIF(成品月初库存!$C$3:$C$362,$B81,成品月初库存!$F$3:$F$362) -> 530 | H81: =SUMIF(成品入库明细!$D$2:$D$500,$B81,成品入库明细!$G$2:$G$500) -> 0 | I81: =SUMIF(成品出库明细!$D$2:$D$1172,$B81,成品出库明细!$G$2:$G$1172) -> 0 | J81: =G81+H81-I81 -> 530 | K81: 皮膜
A82: 81 | B82: XFT032 | C82: DUD3500D1 | D82: 鑫福泰 | E82: 成品 | F82: PCS | G82: =SUMIF(成品月初库存!$C$3:$C$362,$B82,成品月初库存!$F$3:$F$362) -> 152 | H82: =SUMIF(成品入库明细!$D$2:$D$500,$B82,成品入库明细!$G$2:$G$500) -> 0 | I82: =SUMIF(成品出库明细!$D$2:$D$1172,$B82,成品出库明细!$G$2:$G$1172) -> 3 | J82: =G82+H82-I82 -> 149 | K82: 洗白
B83: XFT033 | C83: VSD9007S2 | D83: 鑫福泰 | E83: 成品 | F83: PCS | G83: =SUMIF(成品月初库存!$C$3:$C$362,$B83,成品月初库存!$F$3:$F$362) -> 1676 | H83: =SUMIF(成品入库明细!$D$2:$D$500,$B83,成品入库明细!$G$2:$G$500) -> 0 | I83: =SUMIF(成品出库明细!$D$2:$D$1172,$B83,成品出库明细!$G$2:$G$1172) -> 0 | J83: =G83+H83-I83 -> 1676 | K83: 拉白
B84: XFT034 | C84: (002)Kreka MHSP Tool | D84: 鑫福泰 | E84: 成品 | F84: PCS | G84: =SUMIF(成品月初库存!$C$3:$C$362,$B84,成品月初库存!$F$3:$F$362) -> 194 | H84: =SUMIF(成品入库明细!$D$2:$D$500,$B84,成品入库明细!$G$2:$G$500) -> 0 | I84: =SUMIF(成品出库明细!$D$2:$D$1172,$B84,成品出库明细!$G$2:$G$1172) -> 0 | J84: =G84+H84-I84 -> 194 | K84: 皮膜
B85: XFT035 | C85: (001)Kreka Harrier/PHSP | D85: 鑫福泰 | E85: 成品 | F85: PCS | G85: =SUMIF(成品月初库存!$C$3:$C$362,$B85,成品月初库存!$F$3:$F$362) -> 438 | H85: =SUMIF(成品入库明细!$D$2:$D$500,$B85,成品入库明细!$G$2:$G$500) -> 0 | I85: =SUMIF(成品出库明细!$D$2:$D$1172,$B85,成品出库明细!$G$2:$G$1172) -> 0 | J85: =G85+H85-I85 -> 438 | K85: 皮膜
...
